Workbook

Sheet 使い方
A1: はじめに | C1: =HUAWEI製ＰＣＳ接続枚数計算ツール!B3 -> 2025.08.26版
A3: ・本ツールはHUAWEI製ＰＣＳ向けのパネル接続の検討ツールです。
A5: ・本ツールの使用手順は以下のとおりです。
A6: 色付きのセルは左記を示しています | F6: 入力項目 | I6: 計算結果
A7: １．「太陽電池モジュールリスト」シートに接続したいモジュール仕様を入力
A8: ２．「HUAWEI製ＰＣＳ接続枚数計算ツール」シートに接続したいモジュール型番を入力
A9: ３．「HUAWEI製ＰＣＳ接続枚数計算ツール」シートへ検討したいＰＣＳ型番を選択
A10: ４．「HUAWEI製ＰＣＳ接続枚数計算ツール」シートへ「設計条件」欄を入力
A11: ５．「HUAWEI製ＰＣＳ接続枚数計算ツール」シートの標準回路組み合わせに表示されている組み合わせが、計算結果です。詳しくは「表の見方」のシートをご覧ください。
A12: ６．「HUAWEI製ＰＣＳ接続枚数計算ツール」シートの「電圧、最大出力確認（直列数同一,標準直列数）」欄へ接続したい構成を入力することで、想定される電圧、電流値を確認可能です。
A13: ７．「HUAWEI製ＰＣＳ接続枚数計算ツール」シートの「複数直列組み合わせ回路構成判定」で複数の直列数を組み合わせた場合の接続確認が可能です。
A15: ・セル右上に赤い🔻があるセルにはコメントが付いています。 | H15: サンプル
A17: ・初期で「太陽電池モジュールリスト」シートに記載されているモジュール情報は過去に検討した際の情報であり、
A18: 最新ではない可能性がありますので仕様書等をご確認の上、仕様更新をしてください。
A20: ・結晶系パネルに対しての使用を想定した計算結果となります。
A21: 化合物系、薄膜系の計算にも使用可能ですが、これらの低電流パネルで行われる集電しての接続を考慮した計算結果にはなっておりません。
A23: ・ＰＣＳの環境温度は-20度から40度までの範囲の出力をもとに算定しています。
A25: ・条件により過積載が全くできないように表示されるケースがあります。 その際は弊社代理店若しくは弊社担当まで接続枚数検討をご依頼ください。
A27: ・一部機種は皮相電力(力率)、AC出力電圧により接続可能枚数が変わります。
A29: ・本ツールで示された直列数、回路数の範囲外での具体的な接続検討が必要な場合は、弊社代理店若しくは弊社担当までご依頼ください。
A31: ・本ツールの改造は行わないで下さい。
A33: ・本ツールを他社PCSメーカーに公開することは禁止です。

Sheet 表の見方
B25: ※ＰＣＳは２回路につき１ＭＰＰＴとなっています。
B26: ＭＰＰＴ内の直列数は同じになるようにしてください。
B27: やむを得ず異直列が発生する場合は１枚差までとしてください。
B28: （発電への影響を最小限に抑えるためです）
B30: SUN2000-50KTL-JPM0の入力回路の優先順位（参考）

Sheet 使い方 
A1: はじめに | C1: =HUAWEI製ＰＣＳ接続枚数計算ツール!B3 -> 2025.08.26版
A3: ・本ツールはHUAWEI製ＰＣＳ向けのパネル接続の検討ツールです。
A5: ・本ツールの使用手順は以下のとおりです。
A6: 色付きのセルは左記を示しています | F6: 入力項目 | I6: 計算結果
A7: １．「太陽電池モジュールリスト」シートに接続したいモジュール仕様を入力
A8: ２．「HUAWEI製ＰＣＳ接続枚数計算ツール」シートの「ﾓｼﾞｭｰﾙ型式」接続したいモジュール型番を入力
A9: ３．「HUAWEI製ＰＣＳ接続枚数計算ツール」シートの「設計条件」欄を入力
A10: ４．「HUAWEI製ＰＣＳ接続枚数計算ツール」シートの標準回路組み合わせに表示されている組み合わせが、計算結果です。詳しくは「表の見方」のシートをご覧ください。
A11: ５．標準電圧に満たない組み合わせを検討したい場合や、ＰＣＳ定格以上発電時の蓄電池への充電量を確認したい場合は、「SUN2000-4.95KTL-JPL1 接続確認」へ入力下さい。
A15: ・セル右上に赤い🔻があるセルにはコメントが付いています。 | H15: サンプル
A18: ・初期で「太陽電池モジュールリスト」シートに記載されているモジュール情報は過去に検討した際の情報であり、
A19: 最新ではない可能性がありますので仕様書等をご確認の上、仕様更新をしてください。
A21: ・結晶系パネルに対しての使用を想定した計算結果となります。
A22: 化合物系、薄膜系の計算にも使用可能ですが、これらの低電流パネルで行われる集電しての接続を考慮した計算結果にはなっておりません。
A24: ・ＰＣＳの環境温度は-20度から40度までの範囲の出力をもとに算定しています。
A26: ・条件により過積載が全くできないように表示されるケースがあります。 その際は弊社代理店若しくは弊社担当まで接続枚数検討をご依頼ください。
A28: ・本ツールで示された直列数、回路数の範囲外での具体的な接続検討が必要な場合は、弊社代理店若しくは弊社担当までご依頼ください。
A30: ・本ツールの改造は行わないで下さい。
A32: ・本ツールを他社PCSメーカーに公開することは禁止です。

Sheet 表の見方 
B13: ※ＰＣＳは２回路につき１ＭＰＰＴとなっています。
B14: ＭＰＰＴ内の直列数は同じになるようにしてください。
B15: やむを得ず異直列が発生する場合は１枚差までとしてください。
B16: （発電への影響を最小限に抑えるためです）

Sheet HUAWEI製ＰＣＳ接続枚数計算ツール 住宅向け
B2: HUAWEI製ＰＣＳ接続枚数計算ツール | F2: 入力項目 | I2: 計算結果
B4: 太陽電池モジュール条件
B5: ﾓｼﾞｭｰﾙ型式 | C5: XLB120-380LD-2 | F5: 最大動作電流(Imax) | G5: =VLOOKUP($C$5, 太陽電池モジュールリスト!A:J, 6,FALSE) -> 13.188 | H5: 短絡電流(Isc) | I5: =VLOOKUP($C$5, 太陽電池モジュールリスト!A:J, 5,FALSE) -> 14.376 | J5: 短絡電流温度係数(％/℃) | K5: =VLOOKUP($C$5, 太陽電池モジュールリスト!A:J, 9,FALSE) -> 0.00048
B6: 最大出力（Pmax） | C6: =VLOOKUP($C$5, 太陽電池モジュールリスト!A:J, 2,FALSE) -> 456 | D6: 最大出力温度係数(％/℃) | E6: =VLOOKUP($C$5, 太陽電池モジュールリスト!A:J, 7,FALSE) -> -0.0035 | F6: 最大動作電圧（Vmax） | G6: =VLOOKUP($C$5, 太陽電池モジュールリスト!A:J, 4,FALSE) -> 34.6 | H6: 開放電圧(Voc) | I6: =VLOOKUP($C$5, 太陽電池モジュールリスト!A:J, 3,FALSE) -> 41.7 | J6: 開放電圧温度係数(％/℃) | K6: =VLOOKUP($C$5, 太陽電池モジュールリスト!A:J, 8,FALSE) -> -0.0027
B7: 接続希望パネル枚数(PCS1台につき) | E7: 20 | F7: 過積載率 | H7: =+E7*C6/1000/VLOOKUP($C$9,$B$43:$P$61,2,FALSE) -> 1.8424242
B9: PCS型式 | C9: SUN2000-4.95KTL-JPL1
B11: 設計条件
B12: 環境温度 | D12: 発電によるパネル温度上昇 | G12: ＤＣ電圧降下 | J12: 最大短絡電流制限
B13: 高温時 | C13: 40 | D13: 最大温度上昇 | F13: 30 | G13: パネル過積載時 | I13: 0 | J13: 適用
B14: 低温時 | C14: -20 | G14: パネル非過積載時 | I14: 0.02 | J14: =IF(J13="非適用","最大短絡電流を超えるパネルの接続は極性の逆接続時の故障リスクが高くなりますのでご注意ください","")
B16: 標準設計目安 | C16: 定格出力を出力するには下記の直列数範囲のストリングが必要です。
B17: 最小直列数 | C17: =E33 -> 8 | D17: MPPT辺りの入力可能回路数 | G17: =+M32 -> 1
B18: 最大直列数 | C18: =IFERROR(MIN(C33,G33,U28),C33) -> 12 | D18: 最大入力回路数 | G18: =+M34 -> 2 | H18: 最大過積載率 | J18: =MIN(H7,AA28) -> 1.8424242
B20: SUN2000-4.95KTL-JPL1 低電圧接続検討 | F20: 起動電圧である100V+α程度での接続は低日照時の電圧低下による発電時間の減少リスクがあります。
B21: MPPT1入力直列数 | D21: 4 | E21: MPPT1入力回路数 | G21: 1 | H21: 接続パネル容量 | J21: =(D21*G21+D22*+G22)*C6*0.001 -> 3.648
B22: MPPT2入力直列数 | D22: 4 | E22: MPPT2入力回路数 | G22: 1 | H22: ＰＣＳ最大出力電力 | J22: =IF(MIN(MIN(C39,C40)+MIN(D39,D40),MAX(C39,D39))>=4.95,MIN(J21,4.95),MIN(MIN(C39,C40)+MIN(D39,D40),MAX(C39,D39))) -> 2.7225 | K22: 接続可否 | M22: =IF(AND(G39="接続可能",I39="接続可能",K38="接続可能"),G38,"接続不可") -> 制限あり
M23: =IF(M22="接続不可",IF(K38="接続可能",IF(I39="接続可能","直列数が多すぎます","直列数が少なすぎます"),K38),"")
B27: パネル温度係数計算
B28: 最大動作電流(低温) | C28: =$G$5*(1+($C$14-25+$F$13)*$K$5) -> 13.093046 | D28: 解放電圧(低温) | E28: =ROUNDUP($I$6*(1+(C14-25)*$K$6),2) -> 46.77 | F28: 運転電圧過積載なし(高温) | H28: =ROUNDDOWN($G$6*(1+(C13-25+$F$13)*$K$6)*(VLOOKUP($C$9,$B$43:$P$61,10,FALSE)-I14),2) -> 28.87 | I28: 最大過積載運転電圧(低温) | K28: =ROUNDUP(((1-1/G31)^0.5*($I$6-$G$6)+$G$6)*(1+($C$14-25+$F$13)*$K$6)*(VLOOKUP($C$9,$B$43:$P$61,10,FALSE)-I13),2) -> 40.4 | L28: 希望過積載運転電圧(高温) | N28: =ROUNDDOWN(((((1-1/MAX(100%,H7))^0.5*($I$6-$G$6)+$G$6)*(1+(C13-25+$F$13)*$K$6))*(VLOOKUP($C$9,$B$43:$P$61,10,FALSE)-I13)),2) -> 33.57 | P28: 最大直列数(低温) | R28: =ROUNDDOWN(G32/N29,0) -> 13 | S28: 希望過積載最大直列数(高温) | U28: =ROUNDDOWN(I32/N28,0) -> 15 | V28: 希望過積載最小直列数(高温) | X28: =ROUNDUP(K32/N28,0) -> 7 | Y28: 最大過積載率 | AA28: =IF(H7>100%,C18*G18*C6/1000/VLOOKUP($C$9,$B$43:$P$61,2,FALSE),100%) -> 2.2109091
B29: 最大動作電流(高温) | C29: =$G$5*(1+($C$13-25+$F$13)*$K$5) -> 13.472861 | D29: 最大短絡電流(高温) | E29: =$I$5*(1+(C13-25+$F$13)*$K$5) -> 14.686522 | I29: 最大過積載運転電圧(高温) | K29: =ROUNDDOWN(((((1-1/I31)^0.5*($I$6-$G$6)+$G$6)*(1+(C13-25+$F$13)*$K$6))*(VLOOKUP($C$9,$B$43:$P$61,10,FALSE)-I13)),2) -> 34.31 | L29: 希望過積載運転電圧(低温) | N29: =ROUNDUP(((1-1/MAX(100%,H7))^0.5*($I$6-$G$6)+$G$6)*(1+($C$14-25+$F$13)*$K$6)*(VLOOKUP($C$9,$B$43:$P$61,10,FALSE)-I13),2) -> 39.77 | P29: 最大直流電圧(低温) | R29: =R28*$N$29 -> 517.01 | S29: 希望過積載最大直流電圧(高温) | U29: =U28*$N$28 -> 503.55 | V29: 希望過積載最小直流電圧(高温) | X29: =X28*$N$28 -> 234.99
B31: 標準設計目安計算 | F31: 過積載率 | G31: =IF(M32=1,R28*C6*VLOOKUP($C$9,$B$43:$P$61,9,FALSE)/1000/VLOOKUP($C$9,$B$43:$P$61,2,FALSE)/2,R28*C6*VLOOKUP($C$9,$B$43:$P$61,9,FALSE)/1000/VLOOKUP($C$9,$B$43:$P$61,2,FALSE)) -> 2.3951515 | H31: 過積載率 | I31: =IF(M32=1,U28*C6*VLOOKUP($C$9, $B$43:$P$61, 9,FALSE)/1000/VLOOKUP($C$9, $B$43:$P$61,2,FALSE)/2,U28*C6*VLOOKUP($C$9, $B$43:$P$61, 9,FALSE)/1000/VLOOKUP($C$9, $B$43:$P$61,2,FALSE)) -> 2.7636364 | J31: 過積載率 | K31: =IF(O32=1,X28*C6*VLOOKUP($C$9, $B$43:$P$61, 9,FALSE)/1000/VLOOKUP($C$9, $B$43:$P$61,2,FALSE)/2,X28*C6*VLOOKUP($C$9, $B$43:$P$61, 9,FALSE)/1000/VLOOKUP($C$9, $B$43:$P$61,2,FALSE)) -> 1.289697 | L31: MPPT短絡電流 | M31: =VLOOKUP($C$9, $B$43:$P$61, 7,FALSE) -> 25 | N31: MPPT電流最大回路数 | O31: 1
B32: 最大直流電圧 | C32: =VLOOKUP($C$9, $B$43:$P$61, 3,FALSE) -> 600 | D32: 最小運転電圧(高温) | E32: =VLOOKUP($C$9, $B$43:$P$61, 4,FALSE) -> 220 | F32: 最大運転電圧(低温) | G32: =VLOOKUP($C$9, $B$43:$P$61, 5,FALSE) -> 530 | H32: 最大運転電圧(高温) | I32: =VLOOKUP($C$9, $B$43:$P$61, 6,FALSE) -> 530 | J32: 最小運転電圧(高温) | K32: =VLOOKUP($C$9, $B$43:$P$61, 4,FALSE)*1 -> 220 | L32: MPPT入力回路数 | M32: =IF(J13="非適用",2,IF(ROUNDDOWN(M31/E29,0)>1.9,2,ROUNDDOWN(M31/E29,0))) -> 1 | N32: MPPT電流通常回路数 | O32: =VLOOKUP($C$9, $B$43:$P$61, 9,FALSE)/2-1 -> 1 | Q32: 最大短絡電流制限
B33: 最大直流数(低温) | C33: =ROUNDDOWN(C32/E28,0) -> 12 | D33: 最小直列数(高温) | E33: =ROUNDUP(E32/H28,0) -> 8 | F33: 最大直列数(低温) | G33: =ROUNDDOWN(G32/N29,0) -> 13 | H33: 最大直列数(高温) | I33: =ROUNDDOWN(I32/K29,0) -> 15 | J33: 最小直列数(高温) | K33: =IF(K31>100%,ROUNDUP(K32/K29,0),E33) -> 7 | L33: MPPT短絡電流 | M33: =M32*E29 -> 14.686522 | N33: 最大出力電力 | O33: =MIN(G34,I34,E34)*((O31*VLOOKUP($C$9,B43:P61,8,FALSE)+O32*C28))*0.001 -> 6.71933 | Q33: 適用
B34: 最大解放電圧(低温) | C34: =ROUNDUP(C$33*$E$28,2) -> 561.24 | D34: 最小直流電圧(高温) | E34: =E33*$H$28 -> 230.96 | F34: 最大直流電圧(低温) | G34: =G33*$N$29 -> 517.01 | H34: 最大直流電圧(高温) | I34: =I33*$K$29 -> 514.65 | J34: 最小直流電圧(高温) | K34: =K33*$K$29 -> 240.17 | L34: 入力回路数 | M34: =IF(M32=2,VLOOKUP($C$9,$B$43:$P$61,9,FALSE),IF(M32=0,"接続不可",VLOOKUP($C$9,$B$43:$P$61,9,FALSE)/2)) -> 2 | N34: MPPT制限 | O34: =IF(VLOOKUP($C$9,B43:P61,2,FALSE)>O33,"制限あり","制限なし") -> 制限なし | Q34: 非適用
B36: SUN2000-4.95KTL-JPL1 低電圧,蓄電池接続検討
B37: 最小直流電圧(高温) | C37: =+H28*D21 -> 115.48 | D37: =+H28*D22 -> 115.48 | F37: 4.95KTL-JPL1運転制限
B38: 出力制限 | C38: =ROUNDDOWN((C37-80)/2.33+40,0)/100 -> 0.55 | D38: =ROUNDDOWN((D37-80)/2.33+40,0)/100 -> 0.55 | F38: 運転制限 | G38: =IF(AND(J22<J21,4.95>J22),"制限あり","制限なし") -> 制限あり | H38: 最小電圧 | I38: =IF(OR(C37=0,D37=0),MAX(C37,D37),MIN(C37,D37)) -> 115.48 | J38: 最大短絡電流確認 | K38: =IF(AND(J13="適用",MAX(G21,G22)*E29>M31),"最大短絡電流を超えています","接続可能") -> 接続可能
B39: 制限後出力 | C39: =MIN(C38*4.95) -> 2.7225 | D39: =MIN(D38*4.95) -> 2.7225 | F39: 最大電圧確認 | G39: =IF(MAX(D21,D22)>MIN(C33,R28),"接続不可","接続可能") -> 接続可能 | H39: 最小電圧判定 | I39: =IF(I38>100,"接続可能","接続不可") -> 接続可能
B40: 出力可能電力 | C40: =MIN(D21*G21*C6*0.001) -> 1.824 | D40: =MIN(D22*G22*C6*0.001) -> 1.824
B42: ＰＣＳ機種 | C42: 定格出力 | D42: 最大直流電圧 | E42: 40℃最低直流電圧 | F42: -10℃最大直流電圧 | G42: 40℃最大直流電圧 | H42: 短絡電流 | I42: 入力電流 | J42: 入力回路数 | K42: 変換効率 | M42: 最小電圧 | N42: 最小電圧出力 | O42: 標準電圧 | P42: 電流値
B43: SUN2000-125KTL-JPH0 力率1.0 | C43: 125 | D43: 1500 | E43: 800 | F43: 1200 | G43: 1100 | H43: 50 | I43: 30 | J43: 18 | K43: 0.981
B44: SUN2000-125KTL-JPH0 力率0.9 | C44: 125 | D44: 1500 | E44: 800 | F44: 1200 | G44: 950 | H44: 50 | I44: 30 | J44: 18 | K44: 0.981
B45: SUN2000-111KTL-NHM0 力率1.0 AC420V.440V | C45: 111 | D45: 1020 | E45: 550 | F45: 800 | G45: 670 | H45: 40 | I45: 26 | J45: 20 | K45: 0.981 | M45: 200 | N45: 0.34 | O45: 550
B46: SUN2000-111KTL-NHM0 力率0.9 AC420V.440V | C46: 111 | D46: 1020 | E46: 550 | F46: 800 | G46: 670 | H46: 40 | I46: 26 | J46: 20 | K46: 0.981 | M46: 200 | N46: 0.34 | O46: 550
B47: SUN2000-63KTL-JPM0 | C47: 62.5 | D47: 1020 | E47: 550 | F47: 850 | G47: 800 | H47: 30 | I47: 22 | J47: 12 | K47: 0.986
B48: SUN2000-63KTL-JPH0 | C48: 62.5 | D48: 1500 | E48: 800 | F48: 1200 | G48: 1100 | H48: 33 | I48: 22 | J48: 12 | K48: 0.985
B49: SUN2000-50KTL-JPM0 | C49: 50 | D49: 1020 | E49: 550 | F49: 890 | G49: 800 | H49: 30 | I49: 22 | J49: 12 | K49: 0.986
B50: SUN2000-40KTL-NH AC420V | C50: 40 | D50: 1020 | E50: 550 | F50: 850 | G50: 634 | H50: 40 | I50: 26 | J50: 8 | K50: 0.984
B51: SUN2000-40KTL-NH AC440V | C51: 40 | D51: 1020 | E51: 590 | F51: 850 | G51: 660 | H51: 40 | I51: 26 | J51: 8 | K51: 0.984
B52: SUN2000-33KTL-NH AC420V | C52: 33 | D52: 1020 | E52: 480 | F52: 850 | G52: 660 | H52: 40 | I52: 26 | J52: 8 | K52: 0.985
...

Sheet 太陽電池モジュールリスト
A1: 太陽電池モジュール型式 | B1: 最大出力（Pmax） | C1: 開放電圧(Voc) | D1: 最大動作電圧（Vmax） | E1: 短絡電流(Isc) | F1: 最大動作電流(Imax) | G1: 最大出力温度係数(％/℃) | H1: 開放電圧温度係数(％/℃) | I1: 短絡電流温度係数(％/℃) | J1: 裏面発電量(％) | K1: 集電数
A2: サンプル | B2: 400 | C2: 45 | D2: 40 | E2: 12 | F2: 10 | G2: -0.0035 | H2: -0.0025 | I2: 0.0004
A3: サンプル（集電） | B3: =B2*K3 -> 800 | C3: =C2 -> 45 | D3: =D2 -> 40 | E3: =E2*K3 -> 24 | F3: =F2*K3 -> 20 | G3: =G2 -> -0.0035 | H3: =H2 -> -0.0025 | I3: =I2 -> 0.0004 | K3: 2
A4: サンプル（両面） | B4: =B3*(1+J4) -> 1000 | C4: =C3 -> 45 | D4: =D3 -> 40 | E4: =E3*(1+J4) -> 30 | F4: =F3*(1+J4) -> 25 | G4: =G3 -> -0.0035 | H4: =H3 -> -0.0025 | I4: =I3 -> 0.0004 | J4: 0.25
A5: CS-304B61 | B5: 304 | C5: 40.4 | D5: 33.1 | E5: 9.75 | F5: 9.2 | G5: -0.004 | H5: -0.003 | I5: 0.0005
A6: 260W | B6: 260 | C6: 38.1 | D6: 31.1 | E6: 9.05 | F6: 8.38 | G6: -0.00436 | H6: -0.0033 | I6: 0.0006
A7: 305-Panel | B7: 305 | C7: 39.7 | D7: 32.7 | E7: 9.82 | G7: =-1.12/305 -> -0.0036721311 | H7: =-0.141/39.7 -> -0.0035516373
A8: 48HL4M-DV-455 | B8: 475 | C8: 36.89 | D8: 31.4 | E8: 16.06 | F8: 15.13 | G8: -0.0029 | H8: -0.0025 | I8: 0.00045
A9: 54HL4M-BDV-525 | B9: 525 | C9: 41.46 | D9: 35.05 | E9: 15.78 | F9: 14.98 | G9: -0.0029 | H9: -0.0025 | I9: 0.00045
A10: 590N | B10: 190 | C10: 27.16 | D10: 21.91 | E10: 9.3 | F10: 8.68 | G10: -0.0036 | H10: -0.0028 | I10: 0.00048
A11: 6MN5A210 | B11: 210 | C11: 31.65 | D11: 26.36 | E11: 8.31 | F11: 7.98 | G11: -0.0042 | H11: -0.0032 | I11: 0.0003
A12: AC-320M/60S | B12: 320 | C12: 40.58 | D12: 32.94 | E12: 10.13 | F12: 9.73 | G12: -0.0039 | H12: -0.0029 | I12: 0.0004
A13: AC-330MH/120S | B13: 330 | C13: 40.49 | D13: 33.74 | E13: 10.25 | F13: 9.79 | G13: -0.0039 | H13: -0.0029 | I13: 0.0004
A14: AC-345MH/120S | B14: 345 | C14: 40.98 | D14: 34.45 | E14: 10.47 | F14: 10.02 | G14: -0.0039 | H14: -0.0029 | I14: 0.0004
A15: AC-370MH/120S | B15: 370 | C15: 41.32 | D15: 34.09 | E15: 11.39 | F15: 10.86 | G15: -0.0035 | H15: -0.0027 | I15: 0.00048
A16: AC-370MH/144S | B16: 370 | C16: 47.4 | D16: 39.6 | E16: 9.85 | F16: 9.35 | G16: -0.0039 | H16: -0.0029 | I16: 0.0004
A17: AC-375MH/120S | B17: 375 | C17: 41.56 | D17: 34.29 | E17: 11.46 | F17: 10.94 | G17: -0.0035 | H17: -0.0027 | I17: 0.00048
A18: AC-380MH/120S | B18: 380 | C18: 41.72 | D18: 34.49 | E18: 11.53 | F18: 11.02 | G18: -0.0035 | H18: -0.0027 | I18: 0.00048
A19: AC-400MH/108V | B19: 400 | C19: 37.1 | D19: 31.2 | E19: 13.73 | F19: 12.83 | G19: -0.0035 | H19: -0.0027 | I19: 0.00048
... A25: AC-450MB/144V | B25: 450 | C25: 49.8 | D25: 41.4 | E25: 11.58 | F25: 10.87 | G25: -0.0035 | H25: -0.0029 | I25: 0.00048
A26: AC-450MB/144V-2 | B26: =B25*(1+J26) -> 562.5 | C26: =C25 -> 49.8 | D26: =D25 -> 41.4 | E26: =E25*(1+J26) -> 14.475 | F26: =F25*(1+J26) -> 13.5875 | G26: =G25 -> -0.0035 | H26: =H25 -> -0.0029 | I26: =I25 -> 0.00048 | J26: 0.25
A27: AC-450MH/144S | B27: 450 | C27: 50.1 | D27: 41.39 | E27: 11.48 | F27: 10.88 | G27: -0.0035 | H27: -0.0027 | I27: 0.00048
A28: AC-450MH/144S | B28: 450 | C28: 50.1 | D28: 41.39 | E28: 11.48 | F28: 10.88 | G28: -0.0035 | H28: -0.0027 | I28: 0.00048
A29: AC-455MH/144S | B29: 455 | C29: 50.34 | D29: 41.61 | E29: 11.54 | F29: 10.94 | G29: -0.0035 | H29: -0.0027 | I29: 0.00048
A30: AC-530MH/144V | B30: 530 | C30: 49.25 | D30: 41.4 | E30: 13.73 | F30: 12.81 | G30: -0.0036 | H30: -0.0028 | I30: 0.00045
A31: AC-535MBT/144V | B31: 535 | C31: 49.4 | D31: 41.55 | E31: 13.79 | F31: 12.88 | G31: -0.0035 | H31: -0.0029 | I31: 0.00048
A32: AC-535MBT/144V-2 | B32: =B31*(1+J32) -> 668.75 | C32: =C31 -> 49.4 | D32: =D31 -> 41.55 | E32: =E31*(1+J32) -> 17.2375 | F32: =F31*(1+J32) -> 16.1 | G32: =G31 -> -0.0035 | H32: =H31 -> -0.0029 | I32: =I31 -> 0.00048 | J32: 0.25
A33: AC-540MBT/144V | B33: 540 | C33: 49.55 | D33: 41.7 | E33: 13.85 | F33: 12.95 | G33: -0.0035 | H33: -0.0029 | I33: 0.00048
A34: AC-540MBT/144V-2 | B34: =B33*(1+J34) -> 675 | C34: =C33 -> 49.55 | D34: =D33 -> 41.7 | E34: =E33*(1+J34) -> 17.3125 | F34: =F33*(1+J34) -> 16.1875 | G34: =G33 -> -0.0035 | H34: =H33 -> -0.0029 | I34: =I33 -> 0.00048 | J34: 0.25
A35: AC-540MH/144V | B35: 540 | C35: 49.55 | D35: 41.7 | E35: 13.85 | F35: 12.95 | G35: -0.0036 | H35: -0.0028 | I35: 0.00045
A36: AC-545MH/144V | B36: 545 | C36: 49.7 | D36: 41.85 | E36: 13.91 | F36: 13.03 | G36: -0.0036 | H36: -0.0028 | I36: 0.00045
A37: AC-550MH/144V | B37: 550 | C37: 49.9 | D37: 41.96 | E37: 14 | F37: 13.11 | G37: -0.0036 | H37: -0.0028 | I37: 0.00045
A38: AIKO-A615-MAH72Mw | B38: 615 | C38: 53.59 | D38: 45.11 | E38: 14.1 | F38: 13.64 | G38: -0.0029 | H38: -0.0024 | I38: 0.0005
A39: AIKO-A700-MAE78Dw | B39: 700 | C39: 59.28 | D39: 49.15 | E39: 14.84 | F39: 14.25 | G39: -0.0026 | H39: -0.0022 | I39: 0.0005
A40: AIKO-A700-MAE78Dw （両面） | B40: =B39*(1+J40) -> 875 | C40: =C39 -> 59.28 | D40: =D39 -> 49.15 | E40: =E39*(1+J40) -> 18.55 | F40: =F39*(1+J40) -> 17.8125 | G40: =G39 -> -0.0026 | H40: =H39 -> -0.0022 | I40: =I39 -> 0.0005 | J40: 0.25
A41: AIKO-A770-GRH78Dw | B41: 770 | C41: 59.1 | D41: 48.77 | E41: 16.59 | F41: 15.79 | G41: -0.0026 | H41: -0.0022 | I41: 0.0005
A42: AIKO-A770-GRH78Dw（両面） | B42: =B41*(1+J42) -> 962.5 | C42: =C41 -> 59.1 | D42: =D41 -> 48.77 | E42: =E41*(1+J42) -> 20.7375 | F42: =F41*(1+J42) -> 19.7375 | G42: =G41 -> -0.0026 | H42: =H41 -> -0.0022 | I42: =I41 -> 0.0005 | J42: 0.25
A43: AIKO-G640-MCH72Dw | B43: 640 | C43: 53.8 | D43: 45.1 | E43: 14.9 | F43: 14.2 | G43: -0.0026 | H43: -0.0022 | I43: 0.0005
A44: AIKO-G640-MCH72Dw(両面） | B44: =B43*(1+J44) -> 800 | C44: =C43 -> 53.8 | D44: =D43 -> 45.1 | E44: =E43*(1+J44) -> 18.625 | F44: =F43*(1+J44) -> 17.75 | G44: =G43 -> -0.0026 | H44: =H43 -> -0.0022 | I44: =I43 -> 0.0005 | J44: 0.25
A45: AS-6M120-HC-370 | B45: 370 | C45: 41.6 | D45: 34.6 | E45: 11.3 | F45: 10.7 | G45: -0.0036 | H45: -0.0028 | I45: 0.0005
...

Sheet HUAWEI製ＰＣＳ接続枚数計算ツール
B2: HUAWEI製ＰＣＳ接続枚数計算ツール | F2: 入力項目 | I2: 計算結果
B3: 2025.08.26版
B4: 太陽電池モジュール条件
B5: ﾓｼﾞｭｰﾙ型式 | C5: JKM600N-72HL4-V | F5: 最大動作電流(Imax) | G5: =VLOOKUP($C$5, 太陽電池モジュールリスト!A:J, 6,FALSE) -> 13.62 | H5: 短絡電流(Isc) | I5: =VLOOKUP($C$5, 太陽電池モジュールリスト!A:J, 5,FALSE) -> 14.25 | J5: 短絡電流温度係数(％/℃) | L5: =VLOOKUP($C$5, 太陽電池モジュールリスト!A:J, 9,FALSE) -> 0.00045
B6: 最大出力（Pmax） | C6: =VLOOKUP($C$5, 太陽電池モジュールリスト!A:J, 2,FALSE) -> 600 | D6: 最大出力温度係数(％/℃) | E6: =VLOOKUP($C$5, 太陽電池モジュールリスト!A:J, 7,FALSE) -> -0.0029 | F6: 最大動作電圧（Vmax） | G6: =VLOOKUP($C$5, 太陽電池モジュールリスト!A:J, 4,FALSE) -> 44.06 | H6: 開放電圧(Voc) | I6: =VLOOKUP($C$5, 太陽電池モジュールリスト!A:J, 3,FALSE) -> 52.9 | J6: 開放電圧温度係数(％/℃) | L6: =VLOOKUP($C$5, 太陽電池モジュールリスト!A:J, 8,FALSE) -> -0.0025
B7: 接続希望パネル枚数(PCS1台につき) | E7: 200 | F7: 過積載率 | H7: =+E7*C6/1000/VLOOKUP($C$9,$B$110:$P$139,2,FALSE) -> 0.96
B9: PCS型式 | C9: SUN2000-125KTL-JPH0 皮相140kVA 力率0.9 | F9: 回路数 | G9: =VLOOKUP($C$9, $B$119:$P$149,9,FALSE) -> 18 | H9: 最大電圧 | J9: =VLOOKUP($C$9, $B$119:$P$149, 3,FALSE) -> 1500 | K9: MPPT最大短絡電流 | M9: =VLOOKUP($C$9, $B$119:$P$149,7,FALSE) -> 50
B10: 定格出力 | C10: =VLOOKUP($C$9, $B$119:$P$149,2,FALSE) -> 125 | D10: JIS変換効率 | E10: =VLOOKUP($C$9, $B$119:$P$149,10,FALSE) -> 0.981 | F10: MPPT数 | G10: =VLOOKUP($C$9, $B$119:$T$149,18,FALSE) -> 9 | H10: MPPT電圧範囲 | J10: =VLOOKUP($C$9, $B$119:$P$149,11,FALSE) -> 500-1500Ｖ | K10: MPPT最大入力電流 | M10: =VLOOKUP($C$9, $B$119:$P$149,8,FALSE) -> 30
C11: =IF(OR(C9="SUN2000-125KTL-NHM0 270V",C9="SUN2000-125KTL-NHM0 330V",C9="SUN2000-125KTL-NHM0 380V",C9="SUN2000-62.5KTL-NHM0"),"※リパワリング向けＰＣＳ接続確認時の太陽電池モジュール条件は接続箱で集電された回路数に応じた電流値で検討してください","")
B13: 設計条件 | E13: MEMO
B14: 設置環境温度
B15: 高温時 | C15: 40
B16: 低温時 | C16: -20
B17: 発電によるパネル温度上昇 | E17: ＤＣ電圧降下 | H17: 最大短絡電流制限
B18: 最大温度上昇 | D18: 30 | E18: パネル過積載時 | G18: 0 | H18: 適用 | J18: 「SUN2000-125KTL-JPH0 皮相125kVA 力率1未満」専用設定 | P18: 設置角度要素(南方位、水平のみ対応)
E19: パネル非過積載時 | G19: 0.01 | H19: =IF(H18="非適用","最大短絡電流を超えるパネルの接続は極性の逆接続時の故障リスクが高くなりますのでご注意ください","") | J19: 設定力率(1～0.8) | L19: 0.87 | P19: 適用・非適用 | R19: 非適用
P20: 設置場所緯度 | R20: 33 | S20: パネル設置角度 | U20: 20
B22: 標準設計目安
B23: 最小直列数 | C23: =E108 -> 21 | D23: MPPT辺りの入力可能回路数 | G23: =+M107 -> 2
B24: 最大直列数 | C24: =IFERROR(MIN(C108,G108,#REF!),C108) -> 25 | D24: 最大入力回路数 | G24: =+M109 -> 18 | H24: 最大過積載率 | J24: =MIN(H7,#REF!) -> #REF!
D27: ＭＰＰＴ１ | E27: ＭＰＰＴ２ | F27: ＭＰＰＴ３ | G27: ＭＰＰＴ４ | H27: ＭＰＰＴ５ | I27: ＭＰＰＴ６ | J27: ＭＰＰＴ７ | K27: ＭＰＰＴ８ | L27: ＭＰＰＴ９ | M27: ＭＰＰＴ１０
B28: 直列数 | D28: 21 | E28: 21 | F28: 21 | G28: 21 | H28: 20 | I28: 20 | J28: 20 | K28: 20 | L28: 20 | M28: 13
B29: 並列数 | D29: 2 | E29: 2 | F29: 2 | G29: 2 | H29: 2 | I29: 2 | J29: 2 | K29: 2 | L29: 2 | M29: 1
B30: 枚数 | D30: =D28*D29 -> 42 | E30: =E28*E29 -> 42 | F30: =F28*F29 -> 42 | G30: =G28*G29 -> 42 | H30: =H28*H29 -> 40 | I30: =I28*I29 -> 40 | J30: =J28*J29 -> 40 | K30: =K28*K29 -> 40 | ... M30: =M28*M29 -> 13
B31: 反映条件 | D31: =IF(G$10-1<0,0,1) -> 1 | E31: =IF($G$10-1.9<0,0,1) -> 1 | F31: =IF($G$10-2.9<0,0,1) -> 1 | G31: =IF($G$10-3.9<0,0,1) -> 1 | H31: =IF($G$10-4.9<0,0,1) -> 1 | I31: =IF($G$10-5.9<0,0,1) -> 1 | J31: =IF($G$10-6.9<0,0,1) -> 1 | K31: =IF($G$10-7.9<0,0,1) -> 1 | L31: =IF($G$10-8.9<0,0,1) -> 1 | M31: =IF($G$10-9.9<0,0,1) -> 0 | U31: 過積載係数 | V31: =(D45/(VLOOKUP($C$9,$B$119:$P$149,2,FALSE)*Z113)) -> 1.7664 | W31: 未使用MPPT | X31: =G10-COUNTIF(D33:M33,">0") -> 0 | Y31: MPPT活用判定 | Z31: =IF(AND(X31>0,MAX(D33:M33)>1),"使用されていないMPPTがあります",1) -> 1 | AA31: 低圧高温大 | AB31: =COUNTIF(D38:M38,">"&E107) -> 4
B32: 直列数 | D32: =IF(D$31=1,D28,"") -> 21 | E32: =IF(E$31=1,E28,0) -> 21 | F32: =IF(F$31=1,F28,0) -> 21 | G32: =IF(G$31=1,G28,0) -> 21 | H32: =IF(H$31=1,H28,0) -> 20 | I32: =IF(I$31=1,I28,0) -> 20 | J32: =IF(J$31=1,J28,0) -> 20 | K32: =IF(K$31=1,K28,0) -> 20 | L32: =IF(L$31=1,L28,0) -> 20 | M32: =IF(M$31=1,M28,0) -> 0 | U32: 開放電圧 | V32: =IF(MAX(D37:M37)<$C$107,1,"開放電圧が高いです") -> 1 | W32: 電圧高温 | X32: =IF(AND($D$40<$I$107),1,"最大動作電圧が高いです") -> 1 | Y32: 低温高圧判定 | Z32: =IF(AND(AB34<1,AJ32>AD33),1,"低電圧回路が多すぎます") -> 1 | AA32: 低圧高温少 | AB32: =COUNTIF(D38:M38,"<"&E107) -> 6 | AC32: 低圧高温 | AD32: =SMALL(D32:M32,COUNTIF(D32:M32,0)+1) -> 20 | AE32: ＰＣＳ低圧 | AF32: =VLOOKUP($C$9, $B$119:$Q$149,12,FALSE) -> 500 | AG32: =VLOOKUP($C$9, $B$119:$Q$149,13,FALSE) -> 6.75 | AH32: =VLOOKUP($C$9, $B$119:$Q$149,14,FALSE) -> 60 | AI32: =SMALL(D38:M38,COUNTIF(D38:M38,0)+1) -> 759.2 | AJ32: =ROUNDDOWN((AI32-AF32)/AG32+AH32,0)/100 -> 0.98
B33: 並列数 | D33: =IF(D$31=1,D29,"") -> 2 | E33: =IF(E$31=1,E29,0) -> 2 | F33: =IF(F$31=1,F29,0) -> 2 | G33: =IF(G$31=1,G29,0) -> 2 | H33: =IF(H$31=1,H29,0) -> 2 | I33: =IF(I$31=1,I29,0) -> 2 | J33: =IF(J$31=1,J29,0) -> 2 | K33: =IF(K$31=1,K29,0) -> 2 | L33: =IF(L$31=1,L29,0) -> 2 | M33: =IF(M$31=1,M29,0) -> 0 | U33: 短絡電流 | V33: =IF(OR(H18="非適用",MAX(D41:M41)<M106),1,"短絡電流が高いです") -> 1 | W33: 電圧低温 | X33: =IF($D$39<$G$107,1,"最大動作電圧が高いです") -> 1 | Y33: 最低電圧判定 | Z33: =IF(SMALL(D38:M38,COUNTIF(D38:M38,0)+1)>AF32,1,"直列数が少なすぎます") -> 1 | AA33: 低圧高温 | AB33: =MAX(D38:M38) -> 797.16 | AC33: 低圧高温 | AD33: =(AD32*(C6+(C6*E6*(C15+D18-25)))*SUM(D35:M35)/1000)/D46 -> 0.83472
B34: 枚数 | D34: =IF(D$31=1,D30,"") -> 42 | E34: =IF(E$31=1,E30,0) -> 42 | F34: =IF(F$31=1,F30,0) -> 42 | G34: =IF(G$31=1,G30,0) -> 42 | H34: =IF(H$31=1,H30,0) -> 40 | I34: =IF(I$31=1,I30,0) -> 40 | J34: =IF(J$31=1,J30,0) -> 40 | K34: =IF(K$31=1,K30,0) -> 40 | L34: =IF(L$31=1,L30,0) -> 40 | M34: =IF(M$31=1,M30,0) -> 0 | AA34: 低温普過積載 | AB34: =MAX(D36:M36)*SUM(D35:M35)*C6/1000/D46 -> 0.96
B35: 低圧高温 | D35: =IF(AND($E$107>D38,D33>0),D33,0) -> 0 | E35: =IF(AND($E$107>E38,E33>0),E33,0) -> 0 | F35: =IF(AND($E$107>F38,F33>0),F33,0) -> 0 | G35: =IF(AND($E$107>G38,G33>0),G33,0) -> 0 | H35: =IF(AND($E$107>H38,H33>0),H33,0) -> 2 | I35: =IF(AND($E$107>I38,I33>0),I33,0) -> 2 | J35: =IF(AND($E$107>J38,J33>0),J33,0) -> 2 | K35: =IF(AND($E$107>K38,K33>0),K33,0) -> 2 | ... M35: =IF(AND($E$107>M38,M33>0),M33,0) -> 0
B36: 低温直列 | D36: =IF(0<D35,D32,0) -> 0 | E36: =IF(0<E35,E32,0) -> 0 | F36: =IF(0<F35,F32,0) -> 0 | G36: =IF(0<G35,G32,0) -> 0 | H36: =IF(0<H35,H32,0) -> 20 | I36: =IF(0<I35,I32,0) -> 20 | J36: =IF(0<J35,J32,0) -> 20 | K36: =IF(0<K35,K32,0) -> 20 | ... M36: =IF(0<M35,M32,0) -> 0 | V36: 開放電圧がアラームのしきい値を超えているため、計算結果の開放電圧が検出された際にアラームにより運転ができません。
B37: 解放電圧(低温) | D37: =IF(D31=1,ROUNDUP(D$28*$E$103,2),0) -> 1236.06 | E37: =IF(E31=1,ROUNDUP(E$28*$E$103,2),0) -> 1236.06 | F37: =IF(F31=1,ROUNDUP(F$28*$E$103,2),0) -> 1236.06 | G37: =IF(G31=1,ROUNDUP(G$28*$E$103,2),0) -> 1236.06 | H37: =IF(H31=1,ROUNDUP(H$28*$E$103,2),0) -> 1177.2 | I37: =IF(I31=1,ROUNDUP(I$28*$E$103,2),0) -> 1177.2 | J37: =IF(J31=1,ROUNDUP(J$28*$E$103,2),0) -> 1177.2 | K37: =IF(K31=1,ROUNDUP(K$28*$E$103,2),0) -> 1177.2 | ... M37: =IF(M31=1,ROUNDUP(M$28*$E$103,2),0) -> 0 | V37: 計算結果が仕様書の最大電圧を超えている場合は、故障のリスクがあるため最大直列数を見直してください。
B38: 最小動作電圧(高温) | D38: =IF(D31=1,D28*$H$103,0) -> 797.16 | E38: =IF(E31=1,E28*$H$103,0) -> 797.16 | F38: =IF(F31=1,F28*$H$103,0) -> 797.16 | G38: =IF(G31=1,G28*$H$103,0) -> 797.16 | H38: =IF(H31=1,H28*$H$103,0) -> 759.2 | I38: =IF(I31=1,I28*$H$103,0) -> 759.2 | J38: =IF(J31=1,J28*$H$103,0) -> 759.2 | K38: =IF(K31=1,K28*$H$103,0) -> 759.2 | ... M38: =IF(M31=1,M28*$H$103,0) -> 0 | V38: MPPTに接続されるパネル短絡電流が高すぎるため内部短絡などが発生した際に短絡電流を遮断できず火災に繋がるため避けてください。
B39: 最大動作電圧(低温) | D39: =ROUNDUP(((1-1/MAX(V31,100%))^0.5*($I$6-$G$6)+$G$6)*(1+($C$16-25+$D$18)*$L$6)*(VLOOKUP($C$9,$B$119:$P$149,10,FALSE)-G18),2)*MAX(D32:M32) -> 1066.38 | V39: 赤く表示されている条件下でストリング動作電圧が高すぎるためにPCSで出力の抑制が発生する可能性があります。
B40: 最大動作電圧(高温) | D40: =ROUNDDOWN(((((1-1/MAX(1,V31))^0.5*($I$6-$G$6)+$G$6)*(1+(C15-25+$D$18)*$L$6))*(VLOOKUP($C$9,$B$119:$P$146,10,FALSE)-G18)),2)*MAX(D32:M32) -> 911.82 | V40: 赤く表示されている条件下でストリング動作電圧が低すぎるためにPCSで出力の抑制が発生する可能性があります。
B41: MPPT短絡電流 | D41: =$I$5*D33 -> 28.5 | E41: =$I$5*E33 -> 28.5 | F41: =$I$5*F33 -> 28.5 | G41: =$I$5*G33 -> 28.5 | H41: =$I$5*H33 -> 28.5 | I41: =$I$5*I33 -> 28.5 | J41: =$I$5*J33 -> 28.5 | K41: =$I$5*K33 -> 28.5 | ... M41: =$I$5*M33 -> 0 | V41: 発電を最適化するため全てのMPPTを使用してください。
B42: MPPT運転電流 | D42: =MIN($C$104*D33,$M$10) -> 27.79161 | E42: =MIN($C$104*E33,$M$10) -> 27.79161 | F42: =MIN($C$104*F33,$M$10) -> 27.79161 | G42: =MIN($C$104*G33,$M$10) -> 27.79161 | H42: =MIN($C$104*H33,$M$10) -> 27.79161 | I42: =MIN($C$104*I33,$M$10) -> 27.79161 | J42: =MIN($C$104*J33,$M$10) -> 27.79161 | K42: =MIN($C$104*K33,$M$10) -> 27.79161 | ... M42: =MIN($C$104*M33,$M$10) -> 0 | V42: 低電圧回路が多いことによりPCSで発電の抑制が顕著に出ることが予想されます。
D43: 1 | E43: 2 | F43: 3 | G43: 4 | H43: 5 | I43: 6 | J43: 7 | K43: 8 | L43: 9 | M43: 10 | V43: MPPT運転電圧範囲未満の電圧になり運転できないMPPTが発生する可能性があります。
B44: 接続パネル枚数 | D44: =SUM(D34:M34) -> 368
B45: 接続パネル容量 | D45: =D44*C6/1000 -> 220.8
B46: PCS定格出力 | D46: =C10 -> 125
...

Sheet HUAWEI製ＰＣＳ接続枚数計算ツール 複数直列数
B2: HUAWEI製ＰＣＳ接続枚数計算ツール | F2: 入力項目 | I2: 計算結果
B3: 2022.8.29版
B4: 太陽電池モジュール条件
B5: ﾓｼﾞｭｰﾙ型式 | C5: ND-163AW | F5: 最大動作電流(Imax) | G5: =VLOOKUP($C$5, 太陽電池モジュールリスト!A:J, 6,FALSE) -> 7.65 | H5: 短絡電流(Isc) | I5: =VLOOKUP($C$5, 太陽電池モジュールリスト!A:J, 5,FALSE) -> 8.46 | J5: 短絡電流温度係数(％/℃) | L5: =VLOOKUP($C$5, 太陽電池モジュールリスト!A:J, 9,FALSE) -> 0.0006
B6: 最大出力（Pmax） | C6: =VLOOKUP($C$5, 太陽電池モジュールリスト!A:J, 2,FALSE) -> 163 | D6: 最大出力温度係数(％/℃) | E6: =VLOOKUP($C$5, 太陽電池モジュールリスト!A:J, 7,FALSE) -> -0.0045 | F6: 最大動作電圧（Vmax） | G6: =VLOOKUP($C$5, 太陽電池モジュールリスト!A:J, 4,FALSE) -> 21.31 | H6: 開放電圧(Voc) | I6: =VLOOKUP($C$5, 太陽電池モジュールリスト!A:J, 3,FALSE) -> 25.63 | J6: 開放電圧温度係数(％/℃) | L6: =VLOOKUP($C$5, 太陽電池モジュールリスト!A:J, 8,FALSE) -> -0.0036
B7: 接続希望パネル枚数(PCS1台につき) | E7: 200 | F7: 過積載率 | H7: =+E7*C6/1000/VLOOKUP($C$9,$B$71:$P$89,2,FALSE) -> #N/A
B9: PCS型式 | C9: SUN2000-4.95KTL-NHL2 | F9: 回路数 | G9: =VLOOKUP($C$9, $B$79:$P$101,9,FALSE) -> 4 | H9: 最大電圧 | I9: =VLOOKUP($C$9, $B$79:$P$101, 3,FALSE) -> 600 | J9: 最大短絡電流 | K9: =VLOOKUP($C$9, $B$79:$P$101,7,FALSE) -> 30
B10: 定格出力 | C10: =VLOOKUP($C$9, $B$79:$P$101,2,FALSE) -> 4.95 | D10: JIS変換効率 | E10: =VLOOKUP($C$9, $B$79:$P$101,10,FALSE) -> 0.97 | F10: MPPT数 | G10: =VLOOKUP($C$9, $B$79:$P$101,9,FALSE)/2 -> 2 | H10: MPPT電圧範囲 | I10: =VLOOKUP($C$9, $B$79:$P$101,11,FALSE) -> 90-560Ｖ | J10: 最大入力電流 | K10: =VLOOKUP($C$9, $B$79:$P$101,8,FALSE) -> 16
B12: 設計条件
B13: 環境温度 | D13: 発電によるパネル温度上昇 | G13: ＤＣ電圧降下 | J13: 最大短絡電流制限
B14: 高温時 | C14: 40 | D14: 最大温度上昇 | F14: 30 | G14: パネル過積載時 | I14: 0 | J14: 適用
B15: 低温時 | C15: -20 | G15: パネル非過積載時 | I15: 0.02 | J15: =IF(J14="非適用","最大短絡電流を超えるパネルの接続は極性の逆接続時の故障リスクが高くなりますのでご注意ください","")
B17: 標準設計目安
B18: 最小直列数 | C18: =E69 -> 13 | D18: MPPT辺りの入力可能回路数 | G18: =+M68 -> 2
B19: 最大直列数 | C19: =IFERROR(MIN(C69,G69,#REF!),C69) -> 20 | D19: 最大入力回路数 | G19: =+M70 -> 4 | H19: 最大過積載率 | J19: =MIN(H7,#REF!) -> #REF!
C21: 入力A(MPPT1) | D21: 入力B(MPPT2) | E21: 入力C(MPPT3) | F21: 入力D(MPPT4) | G21: 入力E(MPPT5) | H21: 入力F(MPPT6) | I21: 入力F(MPPT7) | J21: 入力F(MPPT8) | K21: 入力F(MPPT9) | L21: 入力F(MPPT10)
B22: 直列数 | C22: 15 | M22: ⇒下の緑字3箇所に従い、直列数を入力下さい。
B24: 周囲温度（冬場）（℃） | C24: 上記直列数でのVoc(V) | D24: 上記直列数でのVoc(V) | E24: 上記直列数でのVoc(V) | F24: 上記直列数でのVoc(V) | G24: 上記直列数でのVoc(V) | H24: 上記直列数でのVoc(V) | I24: 上記直列数でのVoc(V) | J24: 上記直列数でのVoc(V) | K24: 上記直列数でのVoc(V) | L24: 上記直列数でのVoc(V) | M24: 動作電圧 | N24: ⇒冬場の最低気温を考慮し、「上記直列数でのVoc」の欄が全て青になるように上の直列数を設定して下さい。 ⇒赤くなれば最大直列数を減らしてください。
B25: -20 | C25: =ROUNDUP($I$6*(1+($B25-25)*$L$6),2)*C$22 -> 446.85 | D25: =ROUNDUP($I$6*(1+($B25-25)*$L$6),2)*D$22 -> 0 | E25: =ROUNDUP($I$6*(1+($B25-25)*$L$6),2)*E$22 -> 0 | F25: =ROUNDUP($I$6*(1+($B25-25)*$L$6),2)*F$22 -> 0 | G25: =ROUNDUP($I$6*(1+($B25-25)*$L$6),2)*G$22 -> 0 | H25: =ROUNDUP($I$6*(1+($B25-25)*$L$6),2)*H$22 -> 0 | I25: =ROUNDUP($I$6*(1+($B25-25)*$L$6),2)*I$22 -> 0 | J25: =ROUNDUP($I$6*(1+($B25-25)*$L$6),2)*J$22 -> 0 | ... L25: =ROUNDUP($I$6*(1+($B25-25)*$L$6),2)*L$22 -> 0 | M25: =ROUNDUP(((1-1/MAX($P$41,100%))^0.5*($I$6-$G$6)+$G$6)*(1+($B25-25+$F$14)*$L$6)*(VLOOKUP($C$9,$B$79:$P$101,10,FALSE)-$I$14),2)*MAX($C$22:$L$22) -> 326.85
B26: -15 | C26: =ROUNDUP($I$6*(1+($B26-25)*$L$6),2)*C$22 -> 439.95 | D26: =ROUNDUP($I$6*(1+($B26-25)*$L$6),2)*D$22 -> 0 | E26: =ROUNDUP($I$6*(1+($B26-25)*$L$6),2)*E$22 -> 0 | F26: =ROUNDUP($I$6*(1+($B26-25)*$L$6),2)*F$22 -> 0 | G26: =ROUNDUP($I$6*(1+($B26-25)*$L$6),2)*G$22 -> 0 | H26: =ROUNDUP($I$6*(1+($B26-25)*$L$6),2)*H$22 -> 0 | I26: =ROUNDUP($I$6*(1+($B26-25)*$L$6),2)*I$22 -> 0 | J26: =ROUNDUP($I$6*(1+($B26-25)*$L$6),2)*J$22 -> 0 | ... L26: =ROUNDUP($I$6*(1+($B26-25)*$L$6),2)*L$22 -> 0 | M26: =ROUNDUP(((1-1/MAX($P$41,100%))^0.5*($I$6-$G$6)+$G$6)*(1+($B26-25+$F$14)*$L$6)*(VLOOKUP($C$9,$B$79:$P$101,10,FALSE)-$I$14),2)*MAX($C$22:$L$22) -> 321.3
B27: -10 | C27: =ROUNDUP($I$6*(1+($B27-25)*$L$6),2)*C$22 -> 432.9 | D27: =ROUNDUP($I$6*(1+($B27-25)*$L$6),2)*D$22 -> 0 | E27: =ROUNDUP($I$6*(1+($B27-25)*$L$6),2)*E$22 -> 0 | F27: =ROUNDUP($I$6*(1+($B27-25)*$L$6),2)*F$22 -> 0 | G27: =ROUNDUP($I$6*(1+($B27-25)*$L$6),2)*G$22 -> 0 | H27: =ROUNDUP($I$6*(1+($B27-25)*$L$6),2)*H$22 -> 0 | I27: =ROUNDUP($I$6*(1+($B27-25)*$L$6),2)*I$22 -> 0 | J27: =ROUNDUP($I$6*(1+($B27-25)*$L$6),2)*J$22 -> 0 | ... L27: =ROUNDUP($I$6*(1+($B27-25)*$L$6),2)*L$22 -> 0 | M27: =ROUNDUP(((1-1/MAX($P$41,100%))^0.5*($I$6-$G$6)+$G$6)*(1+($B27-25+$F$14)*$L$6)*(VLOOKUP($C$9,$B$79:$P$101,10,FALSE)-$I$14),2)*MAX($C$22:$L$22) -> 315.75
B28: -5 | C28: =ROUNDUP($I$6*(1+($B28-25)*$L$6),2)*C$22 -> 426 | D28: =ROUNDUP($I$6*(1+($B28-25)*$L$6),2)*D$22 -> 0 | E28: =ROUNDUP($I$6*(1+($B28-25)*$L$6),2)*E$22 -> 0 | F28: =ROUNDUP($I$6*(1+($B28-25)*$L$6),2)*F$22 -> 0 | G28: =ROUNDUP($I$6*(1+($B28-25)*$L$6),2)*G$22 -> 0 | H28: =ROUNDUP($I$6*(1+($B28-25)*$L$6),2)*H$22 -> 0 | I28: =ROUNDUP($I$6*(1+($B28-25)*$L$6),2)*I$22 -> 0 | J28: =ROUNDUP($I$6*(1+($B28-25)*$L$6),2)*J$22 -> 0 | ... L28: =ROUNDUP($I$6*(1+($B28-25)*$L$6),2)*L$22 -> 0 | M28: =ROUNDUP(((1-1/MAX($P$41,100%))^0.5*($I$6-$G$6)+$G$6)*(1+($B28-25+$F$14)*$L$6)*(VLOOKUP($C$9,$B$79:$P$101,10,FALSE)-$I$14),2)*MAX($C$22:$L$22) -> 310.2
B29: 0 | C29: =ROUNDUP($I$6*(1+($B29-25)*$L$6),2)*C$22 -> 419.1 | D29: =ROUNDUP($I$6*(1+($B29-25)*$L$6),2)*D$22 -> 0 | E29: =ROUNDUP($I$6*(1+($B29-25)*$L$6),2)*E$22 -> 0 | F29: =ROUNDUP($I$6*(1+($B29-25)*$L$6),2)*F$22 -> 0 | G29: =ROUNDUP($I$6*(1+($B29-25)*$L$6),2)*G$22 -> 0 | H29: =ROUNDUP($I$6*(1+($B29-25)*$L$6),2)*H$22 -> 0 | I29: =ROUNDUP($I$6*(1+($B29-25)*$L$6),2)*I$22 -> 0 | J29: =ROUNDUP($I$6*(1+($B29-25)*$L$6),2)*J$22 -> 0 | ... L29: =ROUNDUP($I$6*(1+($B29-25)*$L$6),2)*L$22 -> 0 | M29: =ROUNDUP(((1-1/MAX($P$41,100%))^0.5*($I$6-$G$6)+$G$6)*(1+($B29-25+$F$14)*$L$6)*(VLOOKUP($C$9,$B$79:$P$101,10,FALSE)-$I$14),2)*MAX($C$22:$L$22) -> 304.5
B30: 10 | C30: =ROUNDUP($I$6*(1+($B30-25)*$L$6),2)*C$22 -> 405.3 | D30: =ROUNDUP($I$6*(1+($B30-25)*$L$6),2)*D$22 -> 0 | E30: =ROUNDUP($I$6*(1+($B30-25)*$L$6),2)*E$22 -> 0 | F30: =ROUNDUP($I$6*(1+($B30-25)*$L$6),2)*F$22 -> 0 | G30: =ROUNDUP($I$6*(1+($B30-25)*$L$6),2)*G$22 -> 0 | H30: =ROUNDUP($I$6*(1+($B30-25)*$L$6),2)*H$22 -> 0 | I30: =ROUNDUP($I$6*(1+($B30-25)*$L$6),2)*I$22 -> 0 | J30: =ROUNDUP($I$6*(1+($B30-25)*$L$6),2)*J$22 -> 0 | ... L30: =ROUNDUP($I$6*(1+($B30-25)*$L$6),2)*L$22 -> 0 | M30: =ROUNDUP(((1-1/MAX($P$41,100%))^0.5*($I$6-$G$6)+$G$6)*(1+($B30-25+$F$14)*$L$6)*(VLOOKUP($C$9,$B$79:$P$101,10,FALSE)-$I$14),2)*MAX($C$22:$L$22) -> 293.4
B32: 周囲温度（夏場）（℃） | C32: 上記直列数でのVmp(V) | D32: 上記直列数でのVmp(V) | E32: 上記直列数でのVmp(V) | F32: 上記直列数でのVmp(V) | G32: 上記直列数でのVmp(V) | H32: 上記直列数でのVmp(V) | I32: 上記直列数でのVmp(V) | J32: 上記直列数でのVmp(V) | K32: 上記直列数でのVmp(V) | L32: 上記直列数でのVmp(V) | M32: 動作電圧
B33: 30 | C33: =ROUNDDOWN($G$6*(1+($B33-25+$F$14)*$L$6)*(VLOOKUP($C$9,$B$79:$P$101,10,FALSE)-$I$15),2)*C$22 -> 265.35 | D33: =ROUNDDOWN($G$6*(1+($B33-25+$F$14)*$L$6)*(VLOOKUP($C$9,$B$79:$P$101,10,FALSE)-$I$15),2)*D$22 -> 0 | E33: =ROUNDDOWN($G$6*(1+($B33-25+$F$14)*$L$6)*(VLOOKUP($C$9,$B$79:$P$101,10,FALSE)-$I$15),2)*E$22 -> 0 | F33: =ROUNDDOWN($G$6*(1+($B33-25+$F$14)*$L$6)*(VLOOKUP($C$9,$B$79:$P$101,10,FALSE)-$I$15),2)*F$22 -> 0 | G33: =ROUNDDOWN($G$6*(1+($B33-25+$F$14)*$L$6)*(VLOOKUP($C$9,$B$79:$P$101,10,FALSE)-$I$15),2)*G$22 -> 0 | H33: =ROUNDDOWN($G$6*(1+($B33-25+$F$14)*$L$6)*(VLOOKUP($C$9,$B$79:$P$101,10,FALSE)-$I$15),2)*H$22 -> 0 | I33: =ROUNDDOWN($G$6*(1+($B33-25+$F$14)*$L$6)*(VLOOKUP($C$9,$B$79:$P$101,10,FALSE)-$I$15),2)*I$22 -> 0 | J33: =ROUNDDOWN($G$6*(1+($B33-25+$F$14)*$L$6)*(VLOOKUP($C$9,$B$79:$P$101,10,FALSE)-$I$15),2)*J$22 -> 0 | ... L33: =ROUNDDOWN($G$6*(1+($B33-25+$F$14)*$L$6)*(VLOOKUP($C$9,$B$79:$P$101,10,FALSE)-$I$15),2)*L$22 -> 0 | M33: =ROUNDDOWN(((((1-1/MAX(1,$P$41))^0.5*($I$6-$G$6)+$G$6)*(1+($B33-25+$F$14)*$L$6))*(VLOOKUP($C$9,$B$79:$P$96,10,FALSE)-$I$14)),2)*C$22 -> 270.9 | N33: ⇒夏場の最高温度を考慮し、「上記直列数でのVpm」の欄が全て青になるように上の直列数を設定して下さい。 ⇒赤くなれば最大並列数を減らしてください。
B34: 35 | C34: =ROUNDDOWN($G$6*(1+($B34-25+$F$14)*$L$6)*(VLOOKUP($C$9,$B$79:$P$101,10,FALSE)-$I$15),2)*C$22 -> 259.8 | D34: =ROUNDDOWN($G$6*(1+($B34-25+$F$14)*$L$6)*(VLOOKUP($C$9,$B$79:$P$101,10,FALSE)-$I$15),2)*D$22 -> 0 | E34: =ROUNDDOWN($G$6*(1+($B34-25+$F$14)*$L$6)*(VLOOKUP($C$9,$B$79:$P$101,10,FALSE)-$I$15),2)*E$22 -> 0 | F34: =ROUNDDOWN($G$6*(1+($B34-25+$F$14)*$L$6)*(VLOOKUP($C$9,$B$79:$P$101,10,FALSE)-$I$15),2)*F$22 -> 0 | G34: =ROUNDDOWN($G$6*(1+($B34-25+$F$14)*$L$6)*(VLOOKUP($C$9,$B$79:$P$101,10,FALSE)-$I$15),2)*G$22 -> 0 | H34: =ROUNDDOWN($G$6*(1+($B34-25+$F$14)*$L$6)*(VLOOKUP($C$9,$B$79:$P$101,10,FALSE)-$I$15),2)*H$22 -> 0 | I34: =ROUNDDOWN($G$6*(1+($B34-25+$F$14)*$L$6)*(VLOOKUP($C$9,$B$79:$P$101,10,FALSE)-$I$15),2)*I$22 -> 0 | J34: =ROUNDDOWN($G$6*(1+($B34-25+$F$14)*$L$6)*(VLOOKUP($C$9,$B$79:$P$101,10,FALSE)-$I$15),2)*J$22 -> 0 | ... L34: =ROUNDDOWN($G$6*(1+($B34-25+$F$14)*$L$6)*(VLOOKUP($C$9,$B$79:$P$101,10,FALSE)-$I$15),2)*L$22 -> 0 | M34: =ROUNDDOWN(((((1-1/MAX(1,$P$41))^0.5*($I$6-$G$6)+$G$6)*(1+($B34-25+$F$14)*$L$6))*(VLOOKUP($C$9,$B$79:$P$96,10,FALSE)-$I$14)),2)*C$22 -> 265.35
B35: 40 | C35: =ROUNDDOWN($G$6*(1+($B35-25+$F$14)*$L$6)*(VLOOKUP($C$9,$B$79:$P$101,10,FALSE)-$I$15),2)*C$22 -> 254.4 | D35: =ROUNDDOWN($G$6*(1+($B35-25+$F$14)*$L$6)*(VLOOKUP($C$9,$B$79:$P$101,10,FALSE)-$I$15),2)*D$22 -> 0 | E35: =ROUNDDOWN($G$6*(1+($B35-25+$F$14)*$L$6)*(VLOOKUP($C$9,$B$79:$P$101,10,FALSE)-$I$15),2)*E$22 -> 0 | F35: =ROUNDDOWN($G$6*(1+($B35-25+$F$14)*$L$6)*(VLOOKUP($C$9,$B$79:$P$101,10,FALSE)-$I$15),2)*F$22 -> 0 | G35: =ROUNDDOWN($G$6*(1+($B35-25+$F$14)*$L$6)*(VLOOKUP($C$9,$B$79:$P$101,10,FALSE)-$I$15),2)*G$22 -> 0 | H35: =ROUNDDOWN($G$6*(1+($B35-25+$F$14)*$L$6)*(VLOOKUP($C$9,$B$79:$P$101,10,FALSE)-$I$15),2)*H$22 -> 0 | I35: =ROUNDDOWN($G$6*(1+($B35-25+$F$14)*$L$6)*(VLOOKUP($C$9,$B$79:$P$101,10,FALSE)-$I$15),2)*I$22 -> 0 | J35: =ROUNDDOWN($G$6*(1+($B35-25+$F$14)*$L$6)*(VLOOKUP($C$9,$B$79:$P$101,10,FALSE)-$I$15),2)*J$22 -> 0 | ... L35: =ROUNDDOWN($G$6*(1+($B35-25+$F$14)*$L$6)*(VLOOKUP($C$9,$B$79:$P$101,10,FALSE)-$I$15),2)*L$22 -> 0 | M35: =ROUNDDOWN(((((1-1/MAX(1,$P$41))^0.5*($I$6-$G$6)+$G$6)*(1+($B35-25+$F$14)*$L$6))*(VLOOKUP($C$9,$B$79:$P$96,10,FALSE)-$I$14)),2)*C$22 -> 259.8
B37: 並列数 各入力2並列まで | C37: 2 | D37: 2 | E37: 2 | F37: 2 | G37: 2 | H37: 2 | I37: 2 | J37: 2 | K37: 2 | L37: 2 | M37: ⇒並列数を入力下さい。※各入力Impが最大入力電流値を超える分はパワコン側でカットします（過積載可能）。
B38: 上記並列数でのImp | C38: =$E$65*C37 -> 17.37684 | D38: =$E$65*D37 -> 17.37684 | E38: =$E$65*E37 -> 17.37684 | F38: =$E$65*F37 -> 17.37684 | G38: =$E$65*G37 -> 17.37684 | H38: =$E$65*H37 -> 17.37684 | I38: =$E$65*I37 -> 17.37684 | J38: =$E$65*J37 -> 17.37684 | ... L38: =$E$65*L37 -> 17.37684 | M38: ⇒赤くなれば最大並列数を減らしてください。
C40: =C22*C37 -> 30 | D40: =D22*D37 -> 0 | E40: =E22*E37 -> 0 | F40: =F22*F37 -> 0 | G40: =G22*G37 -> 0 | H40: =H22*H37 -> 0 | I40: =I22*I37 -> 0 | J40: =J22*J37 -> 0 | ... L40: =L22*L37 -> 0 | M40: =SUM(C40:L40) -> 30
C41: =C22*C37*$C$6/1000 -> 4.89 | D41: =D22*D37*$C$6/1000 -> 0 | E41: =E22*E37*$C$6/1000 -> 0 | F41: =F22*F37*$C$6/1000 -> 0 | G41: =G22*G37*$C$6/1000 -> 0 | H41: =H22*H37*$C$6/1000 -> 0 | I41: =I22*I37*$C$6/1000 -> 0 | J41: =J22*J37*$C$6/1000 -> 0 | ... L41: =L22*L37*$C$6/1000 -> 0 | M41: =SUM(C41:L41) -> 4.89 | O41: 過積載率 | P41: =$M$41/VLOOKUP($C$9,$B$79:$P$101,2,FALSE) -> 0.98787879
B44: 結果
B45: 積載枚数(枚/PCS) | C45: =$M$40 -> 30
B46: 積載容量(kW/PCS) | C46: =$C$6*$C$45/1000 -> 4.89
B47: 4.95kWパワコン過積載(%) | C47: =$P$41 -> 0.98787879
B52: 電圧、最大出力確認（直列数同一,標準直列数）
B53: 入力直列数 | C53: 16 | D53: 解放電圧(低温) | F53: =ROUNDUP(C$53*$E$64,2) -> 476.64 | G53: 最大動作電圧(低温) | I53: =C53*$G$65 -> 404.32 | J53: MPPT短絡電流 | L53: =IF(VLOOKUP($C$9,$B$79:$P$101,9,FALSE)/2>=$C$54,$E$65,$E$65*2) -> 17.37684 | M53: 2入力ＭＰＰＴ数 | O53: =IF(VLOOKUP($C$9,$B$79:$P$101,9,FALSE)/2>=C54,0,VLOOKUP($C$9,$B$79:$P$101,9,FALSE)/2-O54) -> 3 | P53: 過積載率 | Q53: =+C53*C54*C6/1000/VLOOKUP($C$9,$B$79:$P$101,2,FALSE) -> 2.6343434 | R53: ＰＣＳ出力 | T53: =IF(AND(F53<C68,I53<G68,F54>E68,AND(J14="適用",L54<M67)),(C53*H64*C65*0.001*O54)+((C53*O53*VLOOKUP($C$9,$B$79:$P$101,8,FALSE)*H64*0.001)),"接続不可") -> 10.893327
B54: 入力回路数 | C54: 5 | D54: 最小動作電圧(高温) | F54: =C53*$H$64 -> 271.36 | G54: 最大動作電圧(高温) | I54: =ROUNDDOWN(((((1-1/Q53)^0.5*($I$6-$G$6)+$G$6)*(1+(C14-25+$F$14)*$L$6))*(VLOOKUP($C$9,$B$79:$P$96,10,FALSE)-I14)),2)*C53 -> 321.28 | J54: MPPT運転電流 | L54: =MIN(VLOOKUP($C$9,$B$79:$P$101,8,FALSE),IF(VLOOKUP($C$9,$B$79:$P$101,9,FALSE)/2>=C54,C65,C65*2)) -> 15.7131 | M54: 1入力ＭＰＰＴ数 | O54: =IF(VLOOKUP($C$9,$B$79:$P$101,9,FALSE)/2<C54,VLOOKUP($C$9,$B$79:$P$101,9,FALSE)-C54,C54) -> -1 | P54: 接続可否 | Q54: =IF(AND(F53<C68,I53<G68,F54>E68,I54<I68,AND(J14="適用",L54<M67)),"接続可能","接続不可") -> 接続可能 | R54: 運転電力制限 | T54: =IF(T53="接続不可","接続不可",IF(VLOOKUP($C$9,$B$79:$P$101,8,FALSE)>C65*2,"影響なし",IF(AND(VLOOKUP($C$9,$B$79:$P$101,2,FALSE)>T53,(O53*2+O54)*C53*C6*0.001>VLOOKUP($C$9,$B$79:$P$101,2,FALSE)),"影響あり","影響なし"))) -> 影響なし
Q55: =IF($F$53<$C$68,IF($F$54>$E$68,IF(AND($I$53<$G$68,$I$54<$I$68),"","動作電圧が高すぎます"),"動作電圧が低すぎます"),"開放電圧が高すぎます")
...

Sheet PCS出力の抑制について
B2: なぜ温度で計算が変わるのですか？
B3: 太陽光パネルは太陽光パネル仕様書に記載されている温度特性により電圧、電流が変化します。
B5: 出力の抑制とはなんですか？
B6: 一般的にはディレーティングと呼ばれるものになります。
B7: PCSにはMPPT運転電圧範囲が設定されていますが、運転可能な電圧範囲であり、
B8: 全ての範囲でPCSの定格出力が出せることを示すものではありません。
B9: 太陽光パネルは主に温度により電圧が変化するため電圧の低いとき（高温）、電圧の高いとき（低温）のときに
B10: 本ツールでは定格出力が計算上出せるかを確認しています。
B11: PCSの環境温度もこれには影響し、本ツールでは高温時は周囲温度40度、低温時は-20度にて検討しています。
B12: 他にも機種によりAC電圧や力率が大きく影響する機種についてはそれらを選択するようにしています。
B14: 実環境下では直射日光の有無や換気状況、他熱源との距離などの影響を受けます。
B15: よって本計算ツールの結果によりディレーティングが発生しないことを保証するものでありませんので
B16: ご理解ください。

Sheet 電流値は超えても問題ないのか

Sheet 過積載すると最大動作電圧が変化するのはなぜか 

Sheet 住宅出力
A1: Q.PEAK DUO M-G11 400 | B1: 400 | C1: 37.16 | D1: 31 | E1: 13.54 | F1: 12.9 | G1: -0.0034 | H1: -0.0027 | I1: 0.0004 | J1: 0.97
L2: 90-560Ｖ | M2: 100 | N2: =(220-M2)/(100-O2) -> 2 | O2: 40
B3: ﾓｼﾞｭｰﾙ型式 | C3: =HUAWEI製ＰＣＳ接続枚数計算ツール!C5 -> JKM600N-72HL4-V | F3: 最大動作電流(Imax) | G3: =VLOOKUP($C$3, 太陽電池モジュールリスト!A:J, 6,FALSE) -> 13.62 | H3: 短絡電流(Isc) | I3: =VLOOKUP($C$3, 太陽電池モジュールリスト!A:J, 5,FALSE) -> 14.25 | J3: 短絡電流温度係数(％/℃) | L3: =VLOOKUP($C$3, 太陽電池モジュールリスト!A:J, 9,FALSE) -> 0.00045
B4: 最大出力（Pmax） | C4: =VLOOKUP($C$3, 太陽電池モジュールリスト!A:J, 2,FALSE) -> 600 | D4: 最大出力温度係数(％/℃) | E4: =VLOOKUP($C$3, 太陽電池モジュールリスト!A:J, 7,FALSE) -> -0.0029 | F4: 最大動作電圧（Vmax） | G4: =VLOOKUP($C$3, 太陽電池モジュールリスト!A:J, 4,FALSE) -> 44.06 | H4: 開放電圧(Voc) | I4: =VLOOKUP($C$3, 太陽電池モジュールリスト!A:J, 3,FALSE) -> 52.9 | J4: 開放電圧温度係数(％/℃) | L4: =VLOOKUP($C$3, 太陽電池モジュールリスト!A:J, 8,FALSE) -> -0.0025
C6: 直列数 | D6: =MAX(HUAWEI製ＰＣＳ接続枚数計算ツール!D57,HUAWEI製ＰＣＳ接続枚数計算ツール!D58) -> 5 | F6: 接続枚数 | G6: =HUAWEI製ＰＣＳ接続枚数計算ツール!J57*1000/住宅出力!C4 -> 10
A7: 環境温度 | B7: パネル温度 | C7: パネル電圧 | D7: ストリング電圧 | E7: PCS出力倍率 | F7: PCS出力倍率補正後 | G7: PCS出力 | H7: パネル出力 | I7: パネル出力補正 | J7: 出力抑制値
A8: 40 | B8: =A8+30 -> 70 | C8: =$G$4+$G$4*($B8-25)*$E$4 -> 38.31017 | D8: =C8*$D$6 -> 191.55085 | E8: =ROUNDDOWN((D8-$M$2)/$N$2+$O$2,0)/100 -> 0.85 | F8: =IF(E8>0.99,1,E8) -> 0.85 | G8: =F8*4.95 -> 4.2075 | H8: =$G$6*($C$4+$E$4*$C$4*(B8-25))/1000 -> 5.217 | I8: =IF(H8>4.95,4.95,H8) -> 4.95 | J8: =G8-I8 -> -0.7425
A9: 39 | B9: =A9+30 -> 69 | C9: =$G$4+$G$4*($B9-25)*$E$4 -> 38.437944 | D9: =C9*$D$6 -> 192.18972 | E9: =ROUNDDOWN((D9-$M$2)/$N$2+$O$2,0)/100 -> 0.86 | F9: =IF(E9>0.99,1,E9) -> 0.86 | G9: =F9*4.95 -> 4.257 | H9: =$G$6*($C$4+$E$4*$C$4*(B9-25))/1000 -> 5.2344 | I9: =IF(H9>4.95,4.95,H9) -> 4.95 | J9: =G9-I9 -> -0.693
A10: 38 | B10: =A10+30 -> 68 | C10: =$G$4+$G$4*($B10-25)*$E$4 -> 38.565718 | D10: =C10*$D$6 -> 192.82859 | E10: =ROUNDDOWN((D10-$M$2)/$N$2+$O$2,0)/100 -> 0.86 | F10: =IF(E10>0.99,1,E10) -> 0.86 | G10: =F10*4.95 -> 4.257 | H10: =$G$6*($C$4+$E$4*$C$4*(B10-25))/1000 -> 5.2518 | I10: =IF(H10>4.95,4.95,H10) -> 4.95 | J10: =G10-I10 -> -0.693
A11: 37 | B11: =A11+30 -> 67 | C11: =$G$4+$G$4*($B11-25)*$E$4 -> 38.693492 | D11: =C11*$D$6 -> 193.46746 | E11: =ROUNDDOWN((D11-$M$2)/$N$2+$O$2,0)/100 -> 0.86 | F11: =IF(E11>0.99,1,E11) -> 0.86 | G11: =F11*4.95 -> 4.257 | H11: =$G$6*($C$4+$E$4*$C$4*(B11-25))/1000 -> 5.2692 | I11: =IF(H11>4.95,4.95,H11) -> 4.95 | J11: =G11-I11 -> -0.693
A12: 36 | B12: =A12+30 -> 66 | C12: =$G$4+$G$4*($B12-25)*$E$4 -> 38.821266 | D12: =C12*$D$6 -> 194.10633 | E12: =ROUNDDOWN((D12-$M$2)/$N$2+$O$2,0)/100 -> 0.87 | F12: =IF(E12>0.99,1,E12) -> 0.87 | G12: =F12*4.95 -> 4.3065 | H12: =$G$6*($C$4+$E$4*$C$4*(B12-25))/1000 -> 5.2866 | I12: =IF(H12>4.95,4.95,H12) -> 4.95 | J12: =G12-I12 -> -0.6435
A13: 35 | B13: =A13+30 -> 65 | C13: =$G$4+$G$4*($B13-25)*$E$4 -> 38.94904 | D13: =C13*$D$6 -> 194.7452 | E13: =ROUNDDOWN((D13-$M$2)/$N$2+$O$2,0)/100 -> 0.87 | F13: =IF(E13>0.99,1,E13) -> 0.87 | G13: =F13*4.95 -> 4.3065 | H13: =$G$6*($C$4+$E$4*$C$4*(B13-25))/1000 -> 5.304 | I13: =IF(H13>4.95,4.95,H13) -> 4.95 | J13: =G13-I13 -> -0.6435
A14: 34 | B14: =A14+30 -> 64 | C14: =$G$4+$G$4*($B14-25)*$E$4 -> 39.076814 | D14: =C14*$D$6 -> 195.38407 | E14: =ROUNDDOWN((D14-$M$2)/$N$2+$O$2,0)/100 -> 0.87 | F14: =IF(E14>0.99,1,E14) -> 0.87 | G14: =F14*4.95 -> 4.3065 | H14: =$G$6*($C$4+$E$4*$C$4*(B14-25))/1000 -> 5.3214 | I14: =IF(H14>4.95,4.95,H14) -> 4.95 | J14: =G14-I14 -> -0.6435
A15: 33 | B15: =A15+30 -> 63 | C15: =$G$4+$G$4*($B15-25)*$E$4 -> 39.204588 | D15: =C15*$D$6 -> 196.02294 | E15: =ROUNDDOWN((D15-$M$2)/$N$2+$O$2,0)/100 -> 0.88 | F15: =IF(E15>0.99,1,E15) -> 0.88 | G15: =F15*4.95 -> 4.356 | H15: =$G$6*($C$4+$E$4*$C$4*(B15-25))/1000 -> 5.3388 | I15: =IF(H15>4.95,4.95,H15) -> 4.95 | J15: =G15-I15 -> -0.594
A16: 32 | B16: =A16+30 -> 62 | C16: =$G$4+$G$4*($B16-25)*$E$4 -> 39.332362 | D16: =C16*$D$6 -> 196.66181 | E16: =ROUNDDOWN((D16-$M$2)/$N$2+$O$2,0)/100 -> 0.88 | F16: =IF(E16>0.99,1,E16) -> 0.88 | G16: =F16*4.95 -> 4.356 | H16: =$G$6*($C$4+$E$4*$C$4*(B16-25))/1000 -> 5.3562 | I16: =IF(H16>4.95,4.95,H16) -> 4.95 | J16: =G16-I16 -> -0.594
A17: 31 | B17: =A17+30 -> 61 | C17: =$G$4+$G$4*($B17-25)*$E$4 -> 39.460136 | D17: =C17*$D$6 -> 197.30068 | E17: =ROUNDDOWN((D17-$M$2)/$N$2+$O$2,0)/100 -> 0.88 | F17: =IF(E17>0.99,1,E17) -> 0.88 | G17: =F17*4.95 -> 4.356 | H17: =$G$6*($C$4+$E$4*$C$4*(B17-25))/1000 -> 5.3736 | I17: =IF(H17>4.95,4.95,H17) -> 4.95 | J17: =G17-I17 -> -0.594
A18: 30 | B18: =A18+30 -> 60 | C18: =$G$4+$G$4*($B18-25)*$E$4 -> 39.58791 | D18: =C18*$D$6 -> 197.93955 | E18: =ROUNDDOWN((D18-$M$2)/$N$2+$O$2,0)/100 -> 0.88 | F18: =IF(E18>0.99,1,E18) -> 0.88 | G18: =F18*4.95 -> 4.356 | H18: =$G$6*($C$4+$E$4*$C$4*(B18-25))/1000 -> 5.391 | I18: =IF(H18>4.95,4.95,H18) -> 4.95 | J18: =G18-I18 -> -0.594
A19: 29 | B19: =A19+30 -> 59 | C19: =$G$4+$G$4*($B19-25)*$E$4 -> 39.715684 | D19: =C19*$D$6 -> 198.57842 | E19: =ROUNDDOWN((D19-$M$2)/$N$2+$O$2,0)/100 -> 0.89 | F19: =IF(E19>0.99,1,E19) -> 0.89 | G19: =F19*4.95 -> 4.4055 | H19: =$G$6*($C$4+$E$4*$C$4*(B19-25))/1000 -> 5.4084 | I19: =IF(H19>4.95,4.95,H19) -> 4.95 | J19: =G19-I19 -> -0.5445
... A68: -20 | B68: =A68+30 -> 10 | C68: =$G$4+$G$4*($B68-25)*$E$4 -> 45.97661 | D68: =C68*$D$6 -> 229.88305 | E68: =ROUNDDOWN((D68-$M$2)/$N$2+$O$2,0)/100 -> 1.04 | F68: =IF(E68>0.99,1,E68) -> 1 | G68: =F68*4.95 -> 4.95 | H68: =$G$6*($C$4+$E$4*$C$4*(B68-25))/1000 -> 6.261 | I68: =IF(H68>4.95,4.95,H68) -> 4.95 | J68: =G68-I68 -> 0

Sheet 高電圧出力
A1: 低電圧接続高温電圧
A2: 直列数/回路数 | B2: 1 | C2: 2 | D2: 3 | E2: 4 | F2: 5 | G2: 6 | H2: 7 | I2: 8 | J2: 9 | K2: 10 | L2: 11 | M2: 12 | N2: 13 | O2: 14 | P2: 15 | Q2: 16 | R2: 17 | S2: 18 | T2: 19 | U2: 20 | V2: 21 | W2: 22 | X2: 23 | Y2: 24 | Z2: 25 | AA2: 26 | AB2: 27 | AC2: 28 | AD2: 29 | AE2: 30 | AF2: 31 | AG2: 32 | AH2: 33 | AI2: 34 | AJ2: 35 | AK2: 36 | AL2: 37 | AM2: 38 | AN2: 39 | AO2: 40
A3: 1 | B3: =ROUNDDOWN((高温電圧!B3*高温電圧!B$2-VLOOKUP(HUAWEI製ＰＣＳ接続枚数計算ツール!$C$9, HUAWEI製ＰＣＳ接続枚数計算ツール!$B$119:$P$149,12,FALSE))/VLOOKUP(HUAWEI製ＰＣＳ接続枚数計算ツール!$C$9, HUAWEI製ＰＣＳ接続枚数計算ツール!$B$119:$P$149,13,FALSE)+VLOOKUP(HUAWEI製ＰＣＳ接続枚数計算ツール!$C$9, HUAWEI製ＰＣＳ接続枚数計算ツール!$B$119:$P$149,14,FALSE),0)/100*IF(高温電圧!B3*高温電圧!B$2<VLOOKUP(HUAWEI製ＰＣＳ接続枚数計算ツール!$C$9, HUAWEI製ＰＣＳ接続枚数計算ツール!$B$119:$P$149,12,FALSE),0,1) -> 0 | C3: =ROUNDDOWN((高温電圧!C3*高温電圧!C$2-VLOOKUP(HUAWEI製ＰＣＳ接続枚数計算ツール!$C$9, HUAWEI製ＰＣＳ接続枚数計算ツール!$B$119:$P$149,12,FALSE))/VLOOKUP(HUAWEI製ＰＣＳ接続枚数計算ツール!$C$9, HUAWEI製ＰＣＳ接続枚数計算ツール!$B$119:$P$149,13,FALSE)+VLOOKUP(HUAWEI製ＰＣＳ接続枚数計算ツール!$C$9, HUAWEI製ＰＣＳ接続枚数計算ツール!$B$119:$P$149,14,FALSE),0)/100*IF(高温電圧!C3*高温電圧!C$2<VLOOKUP(HUAWEI製ＰＣＳ接続枚数計算ツール!$C$9, HUAWEI製ＰＣＳ接続枚数計算ツール!$B$119:$P$149,12,FALSE),0,1) -> 0 | D3: =ROUNDDOWN((高温電圧!D3*高温電圧!D$2-VLOOKUP(HUAWEI製ＰＣＳ接続枚数計算ツール!$C$9, HUAWEI製ＰＣＳ接続枚数計算ツール!$B$119:$P$149,12,FALSE))/VLOOKUP(HUAWEI製ＰＣＳ接続枚数計算ツール!$C$9, HUAWEI製ＰＣＳ接続枚数計算ツール!$B$119:$P$149,13,FALSE)+VLOOKUP(HUAWEI製ＰＣＳ接続枚数計算ツール!$C$9, HUAWEI製ＰＣＳ接続枚数計算ツール!$B$119:$P$149,14,FALSE),0)/100*IF(高温電圧!D3*高温電圧!D$2<VLOOKUP(HUAWEI製ＰＣＳ接続枚数計算ツール!$C$9, HUAWEI製ＰＣＳ接続枚数計算ツール!$B$119:$P$149,12,FALSE),0,1) -> 0 | E3: =ROUNDDOWN((高温電圧!E3*高温電圧!E$2-VLOOKUP(HUAWEI製ＰＣＳ接続枚数計算ツール!$C$9, HUAWEI製ＰＣＳ接続枚数計算ツール!$B$119:$P$149,12,FALSE))/VLOOKUP(HUAWEI製ＰＣＳ接続枚数計算ツール!$C$9, HUAWEI製ＰＣＳ接続枚数計算ツール!$B$119:$P$149,13,FALSE)+VLOOKUP(HUAWEI製ＰＣＳ接続枚数計算ツール!$C$9, HUAWEI製ＰＣＳ接続枚数計算ツール!$B$119:$P$149,14,FALSE),0)/100*IF(高温電圧!E3*高温電圧!E$2<VLOOKUP(HUAWEI製ＰＣＳ接続枚数計算ツール!$C$9, HUAWEI製ＰＣＳ接続枚数計算ツール!$B$119:$P$149,12,FALSE),0,1) -> 0 | F3: =ROUNDDOWN((高温電圧!F3*高温電圧!F$2-VLOOKUP(HUAWEI製ＰＣＳ接続枚数計算ツール!$C$9, HUAWEI製ＰＣＳ接続枚数計算ツール!$B$119:$P$149,12,FALSE))/VLOOKUP(HUAWEI製ＰＣＳ接続枚数計算ツール!$C$9, HUAWEI製ＰＣＳ接続枚数計算ツール!$B$119:$P$149,13,FALSE)+VLOOKUP(HUAWEI製ＰＣＳ接続枚数計算ツール!$C$9, HUAWEI製ＰＣＳ接続枚数計算ツール!$B$119:$P$149,14,FALSE),0)/100*IF(高温電圧!F3*高温電圧!F$2<VLOOKUP(HUAWEI製ＰＣＳ接続枚数計算ツール!$C$9, HUAWEI製ＰＣＳ接続枚数計算ツール!$B$119:$P$149,12,FALSE),0,1) -> 0 | G3: =ROUNDDOWN((高温電圧!G3*高温電圧!G$2-VLOOKUP(HUAWEI製ＰＣＳ接続枚数計算ツール!$C$9, HUAWEI製ＰＣＳ接続枚数計算ツール!$B$119:$P$149,12,FALSE))/VLOOKUP(HUAWEI製ＰＣＳ接続枚数計算ツール!$C$9, HUAWEI製ＰＣＳ接続枚数計算ツール!$B$119:$P$149,13,FALSE)+VLOOKUP(HUAWEI製ＰＣＳ接続枚数計算ツール!$C$9, HUAWEI製ＰＣＳ接続枚数計算ツール!$B$119:$P$149,14,FALSE),0)/100*IF(高温電圧!G3*高温電圧!G$2<VLOOKUP(HUAWEI製ＰＣＳ接続枚数計算ツール!$C$9, HUAWEI製ＰＣＳ接続枚数計算ツール!$B$119:$P$149,12,FALSE),0,1) -> 0 | H3: =ROUNDDOWN((高温電圧!H3*高温電圧!H$2-VLOOKUP(HUAWEI製ＰＣＳ接続枚数計算ツール!$C$9, HUAWEI製ＰＣＳ接続枚数計算ツール!$B$119:$P$149,12,FALSE))/VLOOKUP(HUAWEI製ＰＣＳ接続枚数計算ツール!$C$9, HUAWEI製ＰＣＳ接続枚数計算ツール!$B$119:$P$149,13,FALSE)+VLOOKUP(HUAWEI製ＰＣＳ接続枚数計算ツール!$C$9, HUAWEI製ＰＣＳ接続枚数計算ツール!$B$119:$P$149,14,FALSE),0)/100*IF(高温電圧!H3*高温電圧!H$2<VLOOKUP(HUAWEI製ＰＣＳ接続枚数計算ツール!$C$9, HUAWEI製ＰＣＳ接続枚数計算ツール!$B$119:$P$149,12,FALSE),0,1) -> 0 | I3: =ROUNDDOWN((高温電圧!I3*高温電圧!I$2-VLOOKUP(HUAWEI製ＰＣＳ接続枚数計算ツール!$C$9, HUAWEI製ＰＣＳ接続枚数計算ツール!$B$119:$P$149,12,FALSE))/VLOOKUP(HUAWEI製ＰＣＳ接続枚数計算ツール!$C$9, HUAWEI製ＰＣＳ接続枚数計算ツール!$B$119:$P$149,13,FALSE)+VLOOKUP(HUAWEI製ＰＣＳ接続枚数計算ツール!$C$9, HUAWEI製ＰＣＳ接続枚数計算ツール!$B$119:$P$149,14,FALSE),0)/100*IF(高温電圧!I3*高温電圧!I$2<VLOOKUP(HUAWEI製ＰＣＳ接続枚数計算ツール!$C$9, HUAWEI製ＰＣＳ接続枚数計算ツール!$B$119:$P$149,12,FALSE),0,1) -> 0 | ... AO3: =ROUNDDOWN((高温電圧!AO3*高温電圧!AO$2-VLOOKUP(HUAWEI製ＰＣＳ接続枚数計算ツール!$C$9, HUAWEI製ＰＣＳ接続枚数計算ツール!$B$119:$P$149,12,FALSE))/VLOOKUP(HUAWEI製ＰＣＳ接続枚数計算ツール!$C$9, HUAWEI製ＰＣＳ接続枚数計算ツール!$B$119:$P$149,13,FALSE)+VLOOKUP(HUAWEI製ＰＣＳ接続枚数計算ツール!$C$9, HUAWEI製ＰＣＳ接続枚数計算ツール!$B$119:$P$149,14,FALSE),0)/100*IF(高温電圧!AO3*高温電圧!AO$2<VLOOKUP(HUAWEI製ＰＣＳ接続枚数計算ツール!$C$9, HUAWEI製ＰＣＳ接続枚数計算ツール!$B$119:$P$149,12,FALSE),0,1) -> 2.1
A4: 2 | B4: =ROUNDDOWN((高温電圧!B4*高温電圧!B$2-VLOOKUP(HUAWEI製ＰＣＳ接続枚数計算ツール!$C$9, HUAWEI製ＰＣＳ接続枚数計算ツール!$B$119:$P$149,12,FALSE))/VLOOKUP(HUAWEI製ＰＣＳ接続枚数計算ツール!$C$9, HUAWEI製ＰＣＳ接続枚数計算ツール!$B$119:$P$149,13,FALSE)+VLOOKUP(HUAWEI製ＰＣＳ接続枚数計算ツール!$C$9, HUAWEI製ＰＣＳ接続枚数計算ツール!$B$119:$P$149,14,FALSE),0)/100*IF(高温電圧!B4*高温電圧!B$2<VLOOKUP(HUAWEI製ＰＣＳ接続枚数計算ツール!$C$9, HUAWEI製ＰＣＳ接続枚数計算ツール!$B$119:$P$149,12,FALSE),0,1) -> 0 | C4: =ROUNDDOWN((高温電圧!C4*高温電圧!C$2-VLOOKUP(HUAWEI製ＰＣＳ接続枚数計算ツール!$C$9, HUAWEI製ＰＣＳ接続枚数計算ツール!$B$119:$P$149,12,FALSE))/VLOOKUP(HUAWEI製ＰＣＳ接続枚数計算ツール!$C$9, HUAWEI製ＰＣＳ接続枚数計算ツール!$B$119:$P$149,13,FALSE)+VLOOKUP(HUAWEI製ＰＣＳ接続枚数計算ツール!$C$9, HUAWEI製ＰＣＳ接続枚数計算ツール!$B$119:$P$149,14,FALSE),0)/100*IF(高温電圧!C4*高温電圧!C$2<VLOOKUP(HUAWEI製ＰＣＳ接続枚数計算ツール!$C$9, HUAWEI製ＰＣＳ接続枚数計算ツール!$B$119:$P$149,12,FALSE),0,1) -> 0 | D4: =ROUNDDOWN((高温電圧!D4*高温電圧!D$2-VLOOKUP(HUAWEI製ＰＣＳ接続枚数計算ツール!$C$9, HUAWEI製ＰＣＳ接続枚数計算ツール!$B$119:$P$149,12,FALSE))/VLOOKUP(HUAWEI製ＰＣＳ接続枚数計算ツール!$C$9, HUAWEI製ＰＣＳ接続枚数計算ツール!$B$119:$P$149,13,FALSE)+VLOOKUP(HUAWEI製ＰＣＳ接続枚数計算ツール!$C$9, HUAWEI製ＰＣＳ接続枚数計算ツール!$B$119:$P$149,14,FALSE),0)/100*IF(高温電圧!D4*高温電圧!D$2<VLOOKUP(HUAWEI製ＰＣＳ接続枚数計算ツール!$C$9, HUAWEI製ＰＣＳ接続枚数計算ツール!$B$119:$P$149,12,FALSE),0,1) -> 0 | E4: =ROUNDDOWN((高温電圧!E4*高温電圧!E$2-VLOOKUP(HUAWEI製ＰＣＳ接続枚数計算ツール!$C$9, HUAWEI製ＰＣＳ接続枚数計算ツール!$B$119:$P$149,12,FALSE))/VLOOKUP(HUAWEI製ＰＣＳ接続枚数計算ツール!$C$9, HUAWEI製ＰＣＳ接続枚数計算ツール!$B$119:$P$149,13,FALSE)+VLOOKUP(HUAWEI製ＰＣＳ接続枚数計算ツール!$C$9, HUAWEI製ＰＣＳ接続枚数計算ツール!$B$119:$P$149,14,FALSE),0)/100*IF(高温電圧!E4*高温電圧!E$2<VLOOKUP(HUAWEI製ＰＣＳ接続枚数計算ツール!$C$9, HUAWEI製ＰＣＳ接続枚数計算ツール!$B$119:$P$149,12,FALSE),0,1) -> 0 | F4: =ROUNDDOWN((高温電圧!F4*高温電圧!F$2-VLOOKUP(HUAWEI製ＰＣＳ接続枚数計算ツール!$C$9, HUAWEI製ＰＣＳ接続枚数計算ツール!$B$119:$P$149,12,FALSE))/VLOOKUP(HUAWEI製ＰＣＳ接続枚数計算ツール!$C$9, HUAWEI製ＰＣＳ接続枚数計算ツール!$B$119:$P$149,13,FALSE)+VLOOKUP(HUAWEI製ＰＣＳ接続枚数計算ツール!$C$9, HUAWEI製ＰＣＳ接続枚数計算ツール!$B$119:$P$149,14,FALSE),0)/100*IF(高温電圧!F4*高温電圧!F$2<VLOOKUP(HUAWEI製ＰＣＳ接続枚数計算ツール!$C$9, HUAWEI製ＰＣＳ接続枚数計算ツール!$B$119:$P$149,12,FALSE),0,1) -> 0 | G4: =ROUNDDOWN((高温電圧!G4*高温電圧!G$2-VLOOKUP(HUAWEI製ＰＣＳ接続枚数計算ツール!$C$9, HUAWEI製ＰＣＳ接続枚数計算ツール!$B$119:$P$149,12,FALSE))/VLOOKUP(HUAWEI製ＰＣＳ接続枚数計算ツール!$C$9, HUAWEI製ＰＣＳ接続枚数計算ツール!$B$119:$P$149,13,FALSE)+VLOOKUP(HUAWEI製ＰＣＳ接続枚数計算ツール!$C$9, HUAWEI製ＰＣＳ接続枚数計算ツール!$B$119:$P$149,14,FALSE),0)/100*IF(高温電圧!G4*高温電圧!G$2<VLOOKUP(HUAWEI製ＰＣＳ接続枚数計算ツール!$C$9, HUAWEI製ＰＣＳ接続枚数計算ツール!$B$119:$P$149,12,FALSE),0,1) -> 0 | H4: =ROUNDDOWN((高温電圧!H4*高温電圧!H$2-VLOOKUP(HUAWEI製ＰＣＳ接続枚数計算ツール!$C$9, HUAWEI製ＰＣＳ接続枚数計算ツール!$B$119:$P$149,12,FALSE))/VLOOKUP(HUAWEI製ＰＣＳ接続枚数計算ツール!$C$9, HUAWEI製ＰＣＳ接続枚数計算ツール!$B$119:$P$149,13,FALSE)+VLOOKUP(HUAWEI製ＰＣＳ接続枚数計算ツール!$C$9, HUAWEI製ＰＣＳ接続枚数計算ツール!$B$119:$P$149,14,FALSE),0)/100*IF(高温電圧!H4*高温電圧!H$2<VLOOKUP(HUAWEI製ＰＣＳ接続枚数計算ツール!$C$9, HUAWEI製ＰＣＳ接続枚数計算ツール!$B$119:$P$149,12,FALSE),0,1) -> 0 | I4: =ROUNDDOWN((高温電圧!I4*高温電圧!I$2-VLOOKUP(HUAWEI製ＰＣＳ接続枚数計算ツール!$C$9, HUAWEI製ＰＣＳ接続枚数計算ツール!$B$119:$P$149,12,FALSE))/VLOOKUP(HUAWEI製ＰＣＳ接続枚数計算ツール!$C$9, HUAWEI製ＰＣＳ接続枚数計算ツール!$B$119:$P$149,13,FALSE)+VLOOKUP(HUAWEI製ＰＣＳ接続枚数計算ツール!$C$9, HUAWEI製ＰＣＳ接続枚数計算ツール!$B$119:$P$149,14,FALSE),0)/100*IF(高温電圧!I4*高温電圧!I$2<VLOOKUP(HUAWEI製ＰＣＳ接続枚数計算ツール!$C$9, HUAWEI製ＰＣＳ接続枚数計算ツール!$B$119:$P$149,12,FALSE),0,1) -> 0 | ... AO4: =ROUNDDOWN((高温電圧!AO4*高温電圧!AO$2-VLOOKUP(HUAWEI製ＰＣＳ接続枚数計算ツール!$C$9, HUAWEI製ＰＣＳ接続枚数計算ツール!$B$119:$P$149,12,FALSE))/VLOOKUP(HUAWEI製ＰＣＳ接続枚数計算ツール!$C$9, HUAWEI製ＰＣＳ接続枚数計算ツール!$B$119:$P$149,13,FALSE)+VLOOKUP(HUAWEI製ＰＣＳ接続枚数計算ツール!$C$9, HUAWEI製ＰＣＳ接続枚数計算ツール!$B$119:$P$149,14,FALSE),0)/100*IF(高温電圧!AO4*高温電圧!AO$2<VLOOKUP(HUAWEI製ＰＣＳ接続枚数計算ツール!$C$9, HUAWEI製ＰＣＳ接続枚数計算ツール!$B$119:$P$149,12,FALSE),0,1) -> 2.1
A5: 3 | B5: =ROUNDDOWN((高温電圧!B5*高温電圧!B$2-VLOOKUP(HUAWEI製ＰＣＳ接続枚数計算ツール!$C$9, HUAWEI製ＰＣＳ接続枚数計算ツール!$B$119:$P$149,12,FALSE))/VLOOKUP(HUAWEI製ＰＣＳ接続枚数計算ツール!$C$9, HUAWEI製ＰＣＳ接続枚数計算ツール!$B$119:$P$149,13,FALSE)+VLOOKUP(HUAWEI製ＰＣＳ接続枚数計算ツール!$C$9, HUAWEI製ＰＣＳ接続枚数計算ツール!$B$119:$P$149,14,FALSE),0)/100*IF(高温電圧!B5*高温電圧!B$2<VLOOKUP(HUAWEI製ＰＣＳ接続枚数計算ツール!$C$9, HUAWEI製ＰＣＳ接続枚数計算ツール!$B$119:$P$149,12,FALSE),0,1) -> 0 | C5: =ROUNDDOWN((高温電圧!C5*高温電圧!C$2-VLOOKUP(HUAWEI製ＰＣＳ接続枚数計算ツール!$C$9, HUAWEI製ＰＣＳ接続枚数計算ツール!$B$119:$P$149,12,FALSE))/VLOOKUP(HUAWEI製ＰＣＳ接続枚数計算ツール!$C$9, HUAWEI製ＰＣＳ接続枚数計算ツール!$B$119:$P$149,13,FALSE)+VLOOKUP(HUAWEI製ＰＣＳ接続枚数計算ツール!$C$9, HUAWEI製ＰＣＳ接続枚数計算ツール!$B$119:$P$149,14,FALSE),0)/100*IF(高温電圧!C5*高温電圧!C$2<VLOOKUP(HUAWEI製ＰＣＳ接続枚数計算ツール!$C$9, HUAWEI製ＰＣＳ接続枚数計算ツール!$B$119:$P$149,12,FALSE),0,1) -> 0 | D5: =ROUNDDOWN((高温電圧!D5*高温電圧!D$2-VLOOKUP(HUAWEI製ＰＣＳ接続枚数計算ツール!$C$9, HUAWEI製ＰＣＳ接続枚数計算ツール!$B$119:$P$149,12,FALSE))/VLOOKUP(HUAWEI製ＰＣＳ接続枚数計算ツール!$C$9, HUAWEI製ＰＣＳ接続枚数計算ツール!$B$119:$P$149,13,FALSE)+VLOOKUP(HUAWEI製ＰＣＳ接続枚数計算ツール!$C$9, HUAWEI製ＰＣＳ接続枚数計算ツール!$B$119:$P$149,14,FALSE),0)/100*IF(高温電圧!D5*高温電圧!D$2<VLOOKUP(HUAWEI製ＰＣＳ接続枚数計算ツール!$C$9, HUAWEI製ＰＣＳ接続枚数計算ツール!$B$119:$P$149,12,FALSE),0,1) -> 0 | E5: =ROUNDDOWN((高温電圧!E5*高温電圧!E$2-VLOOKUP(HUAWEI製ＰＣＳ接続枚数計算ツール!$C$9, HUAWEI製ＰＣＳ接続枚数計算ツール!$B$119:$P$149,12,FALSE))/VLOOKUP(HUAWEI製ＰＣＳ接続枚数計算ツール!$C$9, HUAWEI製ＰＣＳ接続枚数計算ツール!$B$119:$P$149,13,FALSE)+VLOOKUP(HUAWEI製ＰＣＳ接続枚数計算ツール!$C$9, HUAWEI製ＰＣＳ接続枚数計算ツール!$B$119:$P$149,14,FALSE),0)/100*IF(高温電圧!E5*高温電圧!E$2<VLOOKUP(HUAWEI製ＰＣＳ接続枚数計算ツール!$C$9, HUAWEI製ＰＣＳ接続枚数計算ツール!$B$119:$P$149,12,FALSE),0,1) -> 0 | F5: =ROUNDDOWN((高温電圧!F5*高温電圧!F$2-VLOOKUP(HUAWEI製ＰＣＳ接続枚数計算ツール!$C$9, HUAWEI製ＰＣＳ接続枚数計算ツール!$B$119:$P$149,12,FALSE))/VLOOKUP(HUAWEI製ＰＣＳ接続枚数計算ツール!$C$9, HUAWEI製ＰＣＳ接続枚数計算ツール!$B$119:$P$149,13,FALSE)+VLOOKUP(HUAWEI製ＰＣＳ接続枚数計算ツール!$C$9, HUAWEI製ＰＣＳ接続枚数計算ツール!$B$119:$P$149,14,FALSE),0)/100*IF(高温電圧!F5*高温電圧!F$2<VLOOKUP(HUAWEI製ＰＣＳ接続枚数計算ツール!$C$9, HUAWEI製ＰＣＳ接続枚数計算ツール!$B$119:$P$149,12,FALSE),0,1) -> 0 | G5: =ROUNDDOWN((高温電圧!G5*高温電圧!G$2-VLOOKUP(HUAWEI製ＰＣＳ接続枚数計算ツール!$C$9, HUAWEI製ＰＣＳ接続枚数計算ツール!$B$119:$P$149,12,FALSE))/VLOOKUP(HUAWEI製ＰＣＳ接続枚数計算ツール!$C$9, HUAWEI製ＰＣＳ接続枚数計算ツール!$B$119:$P$149,13,FALSE)+VLOOKUP(HUAWEI製ＰＣＳ接続枚数計算ツール!$C$9, HUAWEI製ＰＣＳ接続枚数計算ツール!$B$119:$P$149,14,FALSE),0)/100*IF(高温電圧!G5*高温電圧!G$2<VLOOKUP(HUAWEI製ＰＣＳ接続枚数計算ツール!$C$9, HUAWEI製ＰＣＳ接続枚数計算ツール!$B$119:$P$149,12,FALSE),0,1) -> 0 | H5: =ROUNDDOWN((高温電圧!H5*高温電圧!H$2-VLOOKUP(HUAWEI製ＰＣＳ接続枚数計算ツール!$C$9, HUAWEI製ＰＣＳ接続枚数計算ツール!$B$119:$P$149,12,FALSE))/VLOOKUP(HUAWEI製ＰＣＳ接続枚数計算ツール!$C$9, HUAWEI製ＰＣＳ接続枚数計算ツール!$B$119:$P$149,13,FALSE)+VLOOKUP(HUAWEI製ＰＣＳ接続枚数計算ツール!$C$9, HUAWEI製ＰＣＳ接続枚数計算ツール!$B$119:$P$149,14,FALSE),0)/100*IF(高温電圧!H5*高温電圧!H$2<VLOOKUP(HUAWEI製ＰＣＳ接続枚数計算ツール!$C$9, HUAWEI製ＰＣＳ接続枚数計算ツール!$B$119:$P$149,12,FALSE),0,1) -> 0 | I5: =ROUNDDOWN((高温電圧!I5*高温電圧!I$2-VLOOKUP(HUAWEI製ＰＣＳ接続枚数計算ツール!$C$9, HUAWEI製ＰＣＳ接続枚数計算ツール!$B$119:$P$149,12,FALSE))/VLOOKUP(HUAWEI製ＰＣＳ接続枚数計算ツール!$C$9, HUAWEI製ＰＣＳ接続枚数計算ツール!$B$119:$P$149,13,FALSE)+VLOOKUP(HUAWEI製ＰＣＳ接続枚数計算ツール!$C$9, HUAWEI製ＰＣＳ接続枚数計算ツール!$B$119:$P$149,14,FALSE),0)/100*IF(高温電圧!I5*高温電圧!I$2<VLOOKUP(HUAWEI製ＰＣＳ接続枚数計算ツール!$C$9, HUAWEI製ＰＣＳ接続枚数計算ツール!$B$119:$P$149,12,FALSE),0,1) -> 0 | ... AO5: =ROUNDDOWN((高温電圧!AO5*高温電圧!AO$2-VLOOKUP(HUAWEI製ＰＣＳ接続枚数計算ツール!$C$9, HUAWEI製ＰＣＳ接続枚数計算ツール!$B$119:$P$149,12,FALSE))/VLOOKUP(HUAWEI製ＰＣＳ接続枚数計算ツール!$C$9, HUAWEI製ＰＣＳ接続枚数計算ツール!$B$119:$P$149,13,FALSE)+VLOOKUP(HUAWEI製ＰＣＳ接続枚数計算ツール!$C$9, HUAWEI製ＰＣＳ接続枚数計算ツール!$B$119:$P$149,14,FALSE),0)/100*IF(高温電圧!AO5*高温電圧!AO$2<VLOOKUP(HUAWEI製ＰＣＳ接続枚数計算ツール!$C$9, HUAWEI製ＰＣＳ接続枚数計算ツール!$B$119:$P$149,12,FALSE),0,1) -> 2.1
A6: 4 | B6: =ROUNDDOWN((高温電圧!B6*高温電圧!B$2-VLOOKUP(HUAWEI製ＰＣＳ接続枚数計算ツール!$C$9, HUAWEI製ＰＣＳ接続枚数計算ツール!$B$119:$P$149,12,FALSE))/VLOOKUP(HUAWEI製ＰＣＳ接続枚数計算ツール!$C$9, HUAWEI製ＰＣＳ接続枚数計算ツール!$B$119:$P$149,13,FALSE)+VLOOKUP(HUAWEI製ＰＣＳ接続枚数計算ツール!$C$9, HUAWEI製ＰＣＳ接続枚数計算ツール!$B$119:$P$149,14,FALSE),0)/100*IF(高温電圧!B6*高温電圧!B$2<VLOOKUP(HUAWEI製ＰＣＳ接続枚数計算ツール!$C$9, HUAWEI製ＰＣＳ接続枚数計算ツール!$B$119:$P$149,12,FALSE),0,1) -> 0 | C6: =ROUNDDOWN((高温電圧!C6*高温電圧!C$2-VLOOKUP(HUAWEI製ＰＣＳ接続枚数計算ツール!$C$9, HUAWEI製ＰＣＳ接続枚数計算ツール!$B$119:$P$149,12,FALSE))/VLOOKUP(HUAWEI製ＰＣＳ接続枚数計算ツール!$C$9, HUAWEI製ＰＣＳ接続枚数計算ツール!$B$119:$P$149,13,FALSE)+VLOOKUP(HUAWEI製ＰＣＳ接続枚数計算ツール!$C$9, HUAWEI製ＰＣＳ接続枚数計算ツール!$B$119:$P$149,14,FALSE),0)/100*IF(高温電圧!C6*高温電圧!C$2<VLOOKUP(HUAWEI製ＰＣＳ接続枚数計算ツール!$C$9, HUAWEI製ＰＣＳ接続枚数計算ツール!$B$119:$P$149,12,FALSE),0,1) -> 0 | D6: =ROUNDDOWN((高温電圧!D6*高温電圧!D$2-VLOOKUP(HUAWEI製ＰＣＳ接続枚数計算ツール!$C$9, HUAWEI製ＰＣＳ接続枚数計算ツール!$B$119:$P$149,12,FALSE))/VLOOKUP(HUAWEI製ＰＣＳ接続枚数計算ツール!$C$9, HUAWEI製ＰＣＳ接続枚数計算ツール!$B$119:$P$149,13,FALSE)+VLOOKUP(HUAWEI製ＰＣＳ接続枚数計算ツール!$C$9, HUAWEI製ＰＣＳ接続枚数計算ツール!$B$119:$P$149,14,FALSE),0)/100*IF(高温電圧!D6*高温電圧!D$2<VLOOKUP(HUAWEI製ＰＣＳ接続枚数計算ツール!$C$9, HUAWEI製ＰＣＳ接続枚数計算ツール!$B$119:$P$149,12,FALSE),0,1) -> 0 | E6: =ROUNDDOWN((高温電圧!E6*高温電圧!E$2-VLOOKUP(HUAWEI製ＰＣＳ接続枚数計算ツール!$C$9, HUAWEI製ＰＣＳ接続枚数計算ツール!$B$119:$P$149,12,FALSE))/VLOOKUP(HUAWEI製ＰＣＳ接続枚数計算ツール!$C$9, HUAWEI製ＰＣＳ接続枚数計算ツール!$B$119:$P$149,13,FALSE)+VLOOKUP(HUAWEI製ＰＣＳ接続枚数計算ツール!$C$9, HUAWEI製ＰＣＳ接続枚数計算ツール!$B$119:$P$149,14,FALSE),0)/100*IF(高温電圧!E6*高温電圧!E$2<VLOOKUP(HUAWEI製ＰＣＳ接続枚数計算ツール!$C$9, HUAWEI製ＰＣＳ接続枚数計算ツール!$B$119:$P$149,12,FALSE),0,1) -> 0 | F6: =ROUNDDOWN((高温電圧!F6*高温電圧!F$2-VLOOKUP(HUAWEI製ＰＣＳ接続枚数計算ツール!$C$9, HUAWEI製ＰＣＳ接続枚数計算ツール!$B$119:$P$149,12,FALSE))/VLOOKUP(HUAWEI製ＰＣＳ接続枚数計算ツール!$C$9, HUAWEI製ＰＣＳ接続枚数計算ツール!$B$119:$P$149,13,FALSE)+VLOOKUP(HUAWEI製ＰＣＳ接続枚数計算ツール!$C$9, HUAWEI製ＰＣＳ接続枚数計算ツール!$B$119:$P$149,14,FALSE),0)/100*IF(高温電圧!F6*高温電圧!F$2<VLOOKUP(HUAWEI製ＰＣＳ接続枚数計算ツール!$C$9, HUAWEI製ＰＣＳ接続枚数計算ツール!$B$119:$P$149,12,FALSE),0,1) -> 0 | G6: =ROUNDDOWN((高温電圧!G6*高温電圧!G$2-VLOOKUP(HUAWEI製ＰＣＳ接続枚数計算ツール!$C$9, HUAWEI製ＰＣＳ接続枚数計算ツール!$B$119:$P$149,12,FALSE))/VLOOKUP(HUAWEI製ＰＣＳ接続枚数計算ツール!$C$9, HUAWEI製ＰＣＳ接続枚数計算ツール!$B$119:$P$149,13,FALSE)+VLOOKUP(HUAWEI製ＰＣＳ接続枚数計算ツール!$C$9, HUAWEI製ＰＣＳ接続枚数計算ツール!$B$119:$P$149,14,FALSE),0)/100*IF(高温電圧!G6*高温電圧!G$2<VLOOKUP(HUAWEI製ＰＣＳ接続枚数計算ツール!$C$9, HUAWEI製ＰＣＳ接続枚数計算ツール!$B$119:$P$149,12,FALSE),0,1) -> 0 | H6: =ROUNDDOWN((高温電圧!H6*高温電圧!H$2-VLOOKUP(HUAWEI製ＰＣＳ接続枚数計算ツール!$C$9, HUAWEI製ＰＣＳ接続枚数計算ツール!$B$119:$P$149,12,FALSE))/VLOOKUP(HUAWEI製ＰＣＳ接続枚数計算ツール!$C$9, HUAWEI製ＰＣＳ接続枚数計算ツール!$B$119:$P$149,13,FALSE)+VLOOKUP(HUAWEI製ＰＣＳ接続枚数計算ツール!$C$9, HUAWEI製ＰＣＳ接続枚数計算ツール!$B$119:$P$149,14,FALSE),0)/100*IF(高温電圧!H6*高温電圧!H$2<VLOOKUP(HUAWEI製ＰＣＳ接続枚数計算ツール!$C$9, HUAWEI製ＰＣＳ接続枚数計算ツール!$B$119:$P$149,12,FALSE),0,1) -> 0 | I6: =ROUNDDOWN((高温電圧!I6*高温電圧!I$2-VLOOKUP(HUAWEI製ＰＣＳ接続枚数計算ツール!$C$9, HUAWEI製ＰＣＳ接続枚数計算ツール!$B$119:$P$149,12,FALSE))/VLOOKUP(HUAWEI製ＰＣＳ接続枚数計算ツール!$C$9, HUAWEI製ＰＣＳ接続枚数計算ツール!$B$119:$P$149,13,FALSE)+VLOOKUP(HUAWEI製ＰＣＳ接続枚数計算ツール!$C$9, HUAWEI製ＰＣＳ接続枚数計算ツール!$B$119:$P$149,14,FALSE),0)/100*IF(高温電圧!I6*高温電圧!I$2<VLOOKUP(HUAWEI製ＰＣＳ接続枚数計算ツール!$C$9, HUAWEI製ＰＣＳ接続枚数計算ツール!$B$119:$P$149,12,FALSE),0,1) -> 0 | ... AO6: =ROUNDDOWN((高温電圧!AO6*高温電圧!AO$2-VLOOKUP(HUAWEI製ＰＣＳ接続枚数計算ツール!$C$9, HUAWEI製ＰＣＳ接続枚数計算ツール!$B$119:$P$149,12,FALSE))/VLOOKUP(HUAWEI製ＰＣＳ接続枚数計算ツール!$C$9, HUAWEI製ＰＣＳ接続枚数計算ツール!$B$119:$P$149,13,FALSE)+VLOOKUP(HUAWEI製ＰＣＳ接続枚数計算ツール!$C$9, HUAWEI製ＰＣＳ接続枚数計算ツール!$B$119:$P$149,14,FALSE),0)/100*IF(高温電圧!AO6*高温電圧!AO$2<VLOOKUP(HUAWEI製ＰＣＳ接続枚数計算ツール!$C$9, HUAWEI製ＰＣＳ接続枚数計算ツール!$B$119:$P$149,12,FALSE),0,1) -> 2.1
